Workbook

Sheet Screener Data>

Sheet BS
C4: 43891 | D4: 44256 | E4: 44621 | F4: 44986 | G4: 45352 | H4: 45717
B5: Equity Capital | C5: 40 | D5: 40 | E5: 40 | F5: 40 | G5: 40 | H5: 41 | K5: Goodwill 6 2,002.25 2,002.25
B6: Reserves | C6: 3445 | D6: 4682 | E6: 6115 | F6: 7395 | G6: 9323 | H6: 14291 | K6: Other intangible assets 6 1,58,833.97 1,70,146.33
B7: Borrowings - | C7: 131 | D7: 241 | E7: 873 | F7: 170 | G7: 207 | H7: 8511 | K7: Intangible assets under development 6 7,469.92 5,695.36
B8: Long term Borrowings | C8: 50 | D8: 58 | E8: 49 | F8: 23 | G8: 25 | H8: 5526 | K8: Right-of-use assets 7 11,906.13 11,436.47
B9: Short term Borrowings | C9: 77 | D9: 177 | E9: 819 | F9: 139 | G9: 171 | H9: 2957 | K9: Investment in associates and joint ventures 8 18,928.24 18,141.12
B10: Lease Liabilities | C10: 4 | D10: 6 | E10: 5 | F10: 8 | G10: 11 | H10: 28
B11: Other Borrowings | C11: 0 | D11: 0 | E11: 0 | F11: 0 | G11: 0
B12: Other Liabilities - | C12: 1449 | D12: 1397 | E12: 2080 | F12: 2080 | G12: 2313 | H12: 4916
B13: Non controlling int | C13: 186 | D13: 141 | E13: 161 | F13: 188 | G13: 213 | H13: 236
B14: Trade Payables | C14: 745 | D14: 667 | E14: 1076 | F14: 1008 | G14: 1103 | H14: 1133
B15: Advance from Customers | C15: 1 | D15: 1 | E15: 1 | F15: 1 | G15: 1
B16: Other liability items | C16: 517 | D16: 588 | E16: 842 | F16: 882 | G16: 996 | H16: 3546
B17: Total Liabilities | C17: 5065 | D17: 6360 | E17: 9108 | F17: 9686 | G17: 11883 | H17: 27760
B18: Fixed Assets - | C18: 1600 | D18: 1664 | E18: 3588 | F18: 4251 | G18: 4545 | H18: 19524
B19: Land | C19: 291 | D19: 291 | E19: 308 | F19: 463 | G19: 465
B20: Building | C20: 565 | D20: 589 | E20: 601 | F20: 1069 | G20: 1279
B21: Plant Machinery | C21: 869 | D21: 979 | E21: 1136 | F21: 1349 | G21: 1696
B22: Equipments | C22: 20 | D22: 34 | E22: 63 | F22: 95 | G22: 110
B23: Computers | C23: 25 | D23: 27 | E23: 32 | F23: 57 | G23: 72
B24: Furniture n fittings | C24: 101 | D24: 111 | E24: 119 | F24: 163 | G24: 191
B25: Vehicles | C25: 32 | D25: 34 | E25: 42 | F25: 71 | G25: 82
B26: Intangible Assets | C26: 68 | D26: 68 | E26: 1861 | F26: 1871 | G26: 1871 | H26: 16616
B27: Other fixed assets | C27: 23 | D27: 33 | E27: 89 | F27: 100 | G27: 150
B28: Gross Block | C28: 1993 | D28: 2166 | E28: 4252 | F28: 5239 | G28: 5915
B29: Accumulated Depreciation | C29: 394 | D29: 501 | E29: 664 | F29: 988 | G29: 1370
B30: CWIP | C30: 317 | D30: 372 | E30: 701 | F30: 550 | G30: 282 | H30: 306
B31: Investments | C31: 829 | D31: 1512 | E31: 1109 | F31: 1346 | G31: 2568 | H31: 2042
B32: Other Assets - | C32: 2319 | D32: 2811 | E32: 3709 | F32: 3538 | G32: 4488 | H32: 5887
B33: Inventories | C33: 899 | D33: 1184 | E33: 1760 | F33: 1498 | G33: 1553 | H33: 2094
B34: Trade receivables | C34: 531 | D34: 331 | E34: 388 | F34: 576 | G34: 848 | H34: 1538
B35: Cash Equivalents | C35: 420 | D35: 701 | E35: 406 | F35: 453 | G35: 1198 | H35: 554
B36: Loans n Advances | C36: 85 | D36: 87 | E36: 208 | F36: 67 | G36: 91 | H36: 204
B37: Other asset items | C37: 384 | D37: 510 | E37: 947 | F37: 943 | G37: 797 | H37: 1497
B38: Total Assets | C38: 5065 | D38: 6360 | E38: 9108 | F38: 9686 | G38: 11883 | H38: 27760
B39: Cash in hand | F39: 45 | G39: 73
B40: Trade receivables | F40: 57642 | G40: 84828
B41: Loan to employees | F41: 163 | G41: 286

Sheet PnL
C3: 42064 | D3: 43891 | E3: 44256 | F3: 44621 | G3: 44986 | H3: 45352 | I3: 45717
B4: Sales - | C4: 3334 | D4: 5865 | E4: 6214 | F4: 7782 | G4: 8749 | H4: 10335 | I4: 12207
B5: Sales Growth % | E5: 0.0595 | F5: 0.2522 | G5: 0.1244 | H5: 0.1812 | I5: 0.1812
B6: Expenses - | C6: 2748 | D6: 4427 | E6: 4565 | F6: 5791 | G6: 6848 | H6: 7796 | I6: 9190
B7: Material Cost % - | C7: 0.4243 | D7: 0.3202 | E7: 0.2865 | F7: 0.3112 | G7: 0.3328 | H7: 0.3066 | I7: 0.2858
B8: Raw material cost | C8: 1504 | D8: 1889 | E8: 2028 | F8: 2871 | G8: 2623 | H8: 3263 | I8: 3672
B9: Change in inventory | C9: -89 | D9: -10 | E9: -247 | F9: -450 | G9: 289 | H9: -95 | I9: -183
B10: Manufacturing Cost % | C10: 0.0028 | D10: 0.0288 | E10: 0.0283 | F10: 0.028 | G10: 0.0284 | H10: 0.0329 | I10: 0
B11: Employee Cost % | C11: 0.1879 | D11: 0.2277 | E11: 0.2278 | F11: 0.2083 | G11: 0.2193 | H11: 0.2202 | I11: 0.2206
B12: Other Cost % | C12: 0.2092 | D12: 0.1781 | E12: 0.192 | F12: 0.1967 | G12: 0.202 | H12: 0.1947 | I12: 0.2464
B13: Operating Profit | C13: 586 | D13: 1438 | E13: 1649 | F13: 1991 | G13: 1902 | H13: 2538 | I13: 3018
B14: OPM % | C14: 0.18 | D14: 0.25 | E14: 0.27 | F14: 0.26 | G14: 0.22 | H14: 0.25 | I14: 0.25
B15: Other Income - | C15: 76 | D15: 122 | E15: 183 | F15: 210 | G15: 141 | H15: 294 | I15: 554
B16: Exceptional items | C16: 0 | D16: 46 | E16: 63 | F16: 87 | G16: 37 | H16: 134 | I16: 5
B17: Other income normal | C17: 76 | D17: 76 | E17: 120 | F17: 123 | G17: 104 | H17: 160 | I17: 549
... B30: Dividend Payout % | C30: 0 | D30: 0 | E30: 0.24 | F30: 0 | G30: 0 | H30: 0 | I30: 0

Sheet CF
C3: 43891 | D3: 44256 | E3: 44621 | F3: 44986 | G3: 45352 | H3: 45717
B4: Cash from Operating Activity - | C4: 1070 | D4: 1137 | E4: 920 | F4: 1813 | G4: 2152 | H4: 2413
B5: Profit from operations | C5: 1546 | D5: 1686 | E5: 2005 | F5: 1970 | G5: 2612 | H5: 3127
B6: Receivables | C6: -313 | D6: 200 | E6: -66 | F6: -205 | G6: -290 | H6: -124
B7: Inventory | C7: -78 | D7: -284 | E7: -577 | F7: 262 | G7: -55 | H7: -221
B8: Payables | C8: 183 | D8: -78 | E8: 420 | F8: -65 | G8: 97 | H8: -146
B9: Other WC items | C9: 63 | D9: 68 | E9: -363 | F9: 175 | G9: 268 | H9: 344
B10: Working capital changes | C10: -145 | D10: -95 | E10: -586 | F10: 167 | G10: 20 | H10: -146
B11: Direct taxes | C11: -331 | D11: -454 | E11: -500 | F11: -323 | G11: -480 | H11: -567
B12: Cash from Investing Activity - | C12: -436 | D12: -1222 | E12: -1369 | F12: -1052 | G12: -2081 | H12: -12683
B13: Fixed assets purchased | C13: -228 | D13: -312 | E13: -2346 | F13: -832 | G13: -389 | H13: -531
B14: Fixed assets sold | C14: 11 | D14: 1 | E14: 3 | F14: 6 | G14: 8 | H14: 12
B15: Investments purchased | C15: -572 | D15: -996 | E15: -1186 | F15: -898 | G15: -1624 | H15: -5471
... B30: Net Cash Flow | C30: 103 | D30: -92 | E30: 156 | F30: 22 | G30: 77 | H30: -37

Sheet Annual Report Data>

Sheet Profit&Loss
J1: -1
B5: Particulars | C5: 2019 | D5: =C5+1 -> 2020 | E5: =D5+1 -> 2021 | F5: =E5+1 -> 2022 | G5: =F5+1 -> 2023 | H5: =G5+1 -> 2024
B6: Revenue from Operations (Net) | C6: 497997.61 | D6: 587186.85 | E6: 622389.82 | F6: 778155.51 | G6: 874943.3 | H6: 1033477.5
B8: Expenses:
B10: Cost of Goods Sold
B11: Cost of raw materials and components consumed | C11: -93227.56 | D11: -129732.17 | E11: -137317.89 | F11: -205756.16 | G11: -181366.35 | H11: -185351.59
B12: Purchases of stock-in-trade | C12: -77713.39 | D12: -59120.53 | E12: -65482.45 | F12: -81375.44 | G12: -80923.76 | H12: -140985.11
B13: Change in inventory | C13: -1192.82 | D13: 1045.59 | E13: 24739.42 | F13: 44958.76 | G13: -29074.09 | H13: 5367.11
B14: Total Cost of Goods Sold | C14: =SUM(C11:C13) -> -172133.77 | D14: =SUM(D11:D13) -> -187807.11 | E14: =SUM(E11:E13) -> -178060.92 | F14: =SUM(F11:F13) -> -242172.84 | G14: =SUM(G11:G13) -> -291364.2 | H14: =SUM(H11:H13) -> -320969.59
B16: Gross Profit | C16: =SUM(C6,C14) -> 325863.84 | D16: =SUM(D6,D14) -> 399379.74 | E16: =SUM(E6,E14) -> 444328.9 | F16: =SUM(F6,F14) -> 535982.67 | G16: =SUM(G6,G14) -> 583579.1 | H16: =SUM(H6,H14) -> 712507.87
B18: SG&A Expenses (Excluding Depreciaion & Interest)
B19: Employee benefit expenses | C19: -109478.58 | D19: -133552.66 | E19: -141578.31 | F19: -162059.33 | G19: -191847.15 | H19: -227473.12
B20: Other expenses | C20: -123939.13 | D20: -112424.52 | E20: -136993.62 | F20: -174988.05 | G20: -201668.29 | H20: -231527.54
B21: Total SG&A Expenses | C21: =SUM(C19:C20) -> -233417.71 | D21: =SUM(D19:D20) -> -245977.18 | E21: =SUM(E19:E20) -> -278571.93 | F21: =SUM(F19:F20) -> -337047.38 | G21: =SUM(G19:G20) -> -393515.44 | H21: =SUM(H19:H20) -> -459000.66
B23: Earnings Before Interest Tax & Depreciation (EBITDA) | C23: =C16+C21 -> 92446.13 | D23: =D16+D21 -> 153402.56 | E23: =E16+E21 -> 165756.97 | F23: =F16+F21 -> 198935.29 | G23: =G16+G21 -> 190063.66 | H23: =H16+H21 -> 253507.21
B25: Less: Depreciation & Amortization | C25: -6903.44 | D25: -9905.84 | E25: -11897.03 | F25: -16661.92 | G25: -32591.95 | H25: -39825.37
B26: Earnings Before Interest & Tax (EBIT) | C26: =C23+C25 -> 85542.69 | D26: =D23+D25 -> 143496.72 | E26: =E23+E25 -> 153859.94 | F26: =F23+F25 -> 182273.37 | G26: =G23+G25 -> 157471.71 | H26: =H23+H25 -> 213681.84
B29: Less: Finance Cost | C29: -4303.24 | D29: -2197.18 | E29: -2014.74 | F29: -5861.04 | G29: -4446.9 | H29: -3353.16
B30: Add: Other Income | C30: 5291.88 | D30: 10378.44 | E30: 16148.21 | F30: 19602.96 | G30: 12856.68 | H30: 28085.79
B32: Profit Before Tax & Exceptional Item | C32: =SUM(C26:C30) -> 86531.33 | D32: =SUM(D26:D30) -> 151677.98 | E32: =SUM(E26:E30) -> 167993.41 | F32: =SUM(F26:F30) -> 196015.29 | G32: =SUM(G26:G30) -> 165881.49 | H32: =SUM(H26:H30) -> 238414.47
B33: Share of net profit of associates and joint ventures | C33: 993.8 | D33: 1153.52 | E33: 1167.71 | F33: 1444.77 | G33: 1242.42 | H33: 1521.35
B35: Profit Before Tax | C35: =C32-C33 -> 85537.53 | D35: =D32-D33 -> 150524.46 | E35: =E32-E33 -> 166825.7 | F35: =F32-F33 -> 194570.52 | G35: =G32-G33 -> 164639.07 | H35: =H32-H33 -> 236893.12
B36: Less: Tax Expenses | C36: -26412.07 | D36: -38159.49 | E36: -39858.39 | F36: -52164.35 | G36: -36156.33 | H36: -45758.65
B37: Profit After Tax | C37: =SUM(C35:C36) -> 59125.46 | D37: =SUM(D35:D36) -> 112364.97 | E37: =SUM(E35:E36) -> 126967.31 | F37: =SUM(F35:F36) -> 142406.17 | G37: =SUM(G35:G36) -> 128482.74 | H37: =SUM(H35:H36) -> 191134.47

Sheet BalanceSheet
B4: Particulars | C4: 2019 | D4: =C4+1 -> 2020 | E4: =D4+1 -> 2021 | F4: =E4+1 -> 2022 | G4: =F4+1 -> 2023 | H4: =G4+1 -> 2024
B5: Non Current Assets
B6: Fixed Assets | C6: =SUM(C7:C13) -> 195336.19 | D6: =SUM(D7:D13) -> 208092.97 | E6: =SUM(E7:E13) -> 220218.16 | F6: =SUM(F7:F13) -> 445741.59 | G6: =SUM(G7:G13) -> 498221.12 | H6: =SUM(H7:H13) -> 501634.45
B7: Property , plant and equipment | C7: 135213.38 | D7: 155134.41 | E7: 162007.07 | F7: 165236.3 | G7: 240943.43 | H7: 281253.16
B8: Capital work in progress | C8: 32680.29 | D8: 31325.86 | E8: 37161.62 | F8: 66987.34 | G8: 49319.2 | H8: 20709.39
B9: Right-of-use-assets | C9: 0 | D9: 0 | E9: 0 | F9: 6735.71 | G9: 11436.47 | H9: 11906.13
B10: Intangible assets | C10: 4732.21 | D10: 4269.44 | E10: 3887.08 | F10: 186305.74 | G10: 172148.58 | H10: 160836.22
B11: Investment properties | C11: 1039.07 | D11: 555.82 | E11: 550.35 | F11: 542.43 | G11: 536.96 | H11: 531.49
B12: Intangible assets under development | C12: 107.06 | D12: 369.46 | E12: 33.36 | F12: 3159.79 | G12: 5695.36 | H12: 7469.92
B13: Investment in associatesand joint ventures | C13: 21564.18 | D13: 16437.98 | E13: 16578.68 | F13: 16774.28 | G13: 18141.12 | H13: 18928.14
B15: Financial assets
B16: Investments | C16: 1.75 | D16: 1.25 | E16: 4001.25 | F16: 6726.5 | G16: 8953.73 | H16: 12052.48
B17: Loans | C17: 7.2 | D17: 9.93 | E17: 7.43 | F17: 2.88 | G17: 0 | H17: 0
B18: Other financial assets | C18: 2694.63 | D18: 3092.99 | E18: 2242.87 | F18: 2292.65 | G18: 11018.14 | H18: 2949.57
B20: Other non-current assets | C20: 3551.11 | D20: 3664.62 | E20: 9667.66 | F20: 7418.43 | G20: 7335.5 | H20: 6628.11
B21: Income tax assets (net) | C21: 6950.53 | D21: 5451.16 | E21: 5560.56 | F21: 7982.42 | G21: 10251.53 | H21: 8198.39
B22: Deferred tax assets (net) | C22: 2889.47 | D22: 4793.16 | E22: 4901.1 | F22: 3928.62 | G22: 2977.69 | H22: 8039.75
B23: Total non-current assets | C23: 211430.88 | D23: 225106.08 | E23: 246599.03 | F23: 474093.09 | G23: 538757.71 | H23: 539502.75
B25: Current Assets
B26: Inventories | C26: 82098.53 | D26: 89913.45 | E26: 118353.77 | F26: 176023.81 | G26: 149845.82 | H26: 155346.12
B27: Trade receivables | C27: 22021.88 | D27: 53109.2 | E27: 33061.13 | F27: 38816.6 | G27: 57642.14 | H27: 84828.12
B28: Other current assets | C28: =SUM(C29:C32) -> 27263.29 | D28: =SUM(D29:D32) -> 30707.63 | E28: =SUM(E29:E32) -> 38556.99 | F28: =SUM(F29:F32) -> 97801.09 | G28: =SUM(G29:G32) -> 72431.97 | H28: =SUM(H29:H32) -> 71040.12
B29: Loans | C29: 3162.02 | D29: 3449.79 | E29: 1841.14 | F29: 119.44 | G29: 163.26 | H29: 286.2
B30: Other financial assets | C30: 366.43 | D30: 448.69 | E30: 999.12 | F30: 1393.71 | G30: 5597.97 | H30: 1316.04
B31: Assets classified as held for sale | C31: 5496.58 | D31: 271.05 | E31: 270.2 | F31: 298.16 | G31: 331.56 | H31: 270.2
B32: Other current assets | C32: 18238.26 | D32: 26538.1 | E32: 35446.53 | F32: 95989.78 | G32: 66339.18 | H32: 69167.68
B33: Cash and cash equivalents | C33: 11639.03 | D33: 22607.53 | E33: 16718.2 | F33: 30253.47 | G33: 30482.07 | H33: 38200.75
B34: Bank balances other than above | C34: 2462.11 | D34: 19380.2 | E34: 53355.98 | F34: 10340.68 | G34: 14837.79 | H34: 81596.37
B35: Total current assets | C35: =SUM(C26:C28,C33,C34) -> 145484.84 | D35: =SUM(D26:D28,D33,D34) -> 215718.01 | E35: =SUM(E26:E28,E33,E34) -> 260046.07 | F35: =SUM(F26:F28,F33,F34) -> 353235.65 | G35: =SUM(G26:G28,G33,G34) -> 325239.79 | H35: =SUM(H26:H28,H33,H34) -> 431011.48
B37: Total Assets | C37: =SUM(C35,C23) -> 356915.72 | D37: =SUM(D35,D23) -> 440824.09 | E37: =SUM(E35,E23) -> 506645.1 | F37: =SUM(F35,F23) -> 827328.74 | G37: =SUM(G35,G23) -> 863997.5 | H37: =SUM(H35,H23) -> 970514.23
A39: Equity & Liabilities
A40: Equity
B41: Equity Share Capital | C41: 4005.88 | D41: 4005.88 | E41: 4005.88 | F41: 4005.88 | G41: 4005.88 | H41: 4005.88
B42: Other Equity | C42: 278299.13 | D42: 344525.14 | E42: 468194.5 | F42: 611517.33 | G42: 739516.4 | H42: 932302.93
B43: EQ attributed to equity holders of parent | C43: 282305.01 | D43: 348531.02 | E43: 472200.38 | F43: 615523.21 | G43: 743522.28 | H43: 936308.81
B44: Non controlling interest | C44: 15862.26 | D44: 18626.11 | E44: 14088.74 | F44: 16107.99 | G44: 18807.01 | H44: 21270
B45: Total Equity | C45: 298167.27 | D45: 367157.13 | E45: 486289.12 | F45: 631631.2 | G45: 762329.29 | H45: 957578.81
A46: Liabilities
B47: Non-current Liabilities
B48: Financial liabilities
...

Sheet CashFlow
C4: 2019 | D4: =C4+1 -> 2020 | E4: =D4+1 -> 2021 | F4: =E4+1 -> 2022 | G4: =F4+1 -> 2023 | H4: =G4+1 -> 2024
A5: 1 | B5: Cash Flow from Operating Activities
B6: PBT | C6: ='Profit&Loss'!C40 -> 0 | D6: ='Profit&Loss'!D40 -> 0 | E6: ='Profit&Loss'!E40 -> 0 | F6: ='Profit&Loss'!F40 -> 0 | G6: ='Profit&Loss'!G40 -> 0 | H6: ='Profit&Loss'!H40 -> 0
B7: Adj to reconcile profit before tax to net CF :
B8: Share of asso and joint ventures | C8: -993.8 | D8: -1153.52 | E8: -1167.71 | F8: -1444.77 | G8: -1242.42 | H8: -1521.35
B9: Dep & Amo expense | C9: 6903.44 | D9: 9905.84 | E9: 11897.03 | F9: 16661.92 | G9: 32591.95 | H9: 39825.37
B10: Net loss/(gain) on current investments measured at FVTPL | C10: -2957.72 | D10: -3505.86 | E10: -6286.49 | F10: -8743.32 | G10: =-162.19+(-3397.58)+(-183.33) -> -3743.1 | H10: =-687.98+(-12847)+(182.28) -> -13352.7
B11: Dividend income from financial assets measured at FVTPL | C11: -31.42 | D11: -428.21 | E11: -42.43 | F11: 0.14 | G11: -0.24 | H11: -0.24
B12: Dividend income from investment measured at FVTPL | C12: - | D12: -0.04 | E12: -0.04 | F12: 0.04 | G12: 0 | H12: 0
B13: Government grant income | C13: -1219.18 | D13: -3456.4 | E13: -4476.82 | F13: -3842.87 | G13: -3682.04 | H13: -7394.94
B14: Unrealized foreign exchange (gain) / loss (net) | C14: 54.31 | D14: 102.5 | E14: -50.24 | F14: -469.32 | G14: 395.84 | H14: -358.65
B15: Exchange difference on translation of financial statements foreign operations | C15: -424.14 | D15: -442.23 | E15: 135.55 | F15: 0 | G15: 0 | H15: 0
B16: Loss/(gain) on disposal of property, plant and equipment (net) | C16: 128 | D16: -193.78 | E16: 304.45 | F16: 374.34 | G16: -166.49 | H16: -48.01
B17: Assets written off | C17: 0 | D17: 0 | E17: 0 | F17: 576.29 | G17: 470.77 | H17: 469.14
B18: Loss/(gain) on sale of investment property (net) | C18: -66.16 | D18: -901.58 | E18: 0 | F18: -0.2 | G18: 0 | H18: 0
B19: Trade and other receivable balances written off | C19: 124.77 | D19: 61.22 | E19: 55.35 | F19: 491.57 | G19: 463.9 | H19: 595.35
B20: Liabilities written back | C20: - | D20: - | E20: -771.24 | F20: -852.65 | G20: -415.34 | H20: -247.92
B21: Allowance for expected credit loss | C21: - | D21: 74.26 | E21: 20.06 | F21: 662.74 | G21: 915.04 | H21: 795.96
B22: Allowance for doubtful loans | C22: 159.19 | D22: 517.52 | E22: 149.25 | F22: 302.61 | G22: 0 | H22: 0
B23: Impairment of non-current assets | C23: 65.04 | D23: 9057.99 | E23: 0 | F23: -800 | G23: 500 | H23: 447.18
B24: Impairment losses on financial assets | C24: - | D24: - | E24: 1771.06 | F24: -1751.3 | G24: 193.52 | H24: 400
B25: Finance income | C25: -561.09 | D25: -1289.51 | E25: -3830.24 | F25: -1292.34 | G25: -1276.4 | H25: -4005.1
B26: Finance costs | C26: 4303.24 | D26: 2171.8 | E26: 1644.59 | F26: =1855.85+278 -> 2133.85 | G26: =4024.3+5.91 -> 4030.21 | H26: =2482.41+2318.63 -> 4801.04
B27: Interest on delay deposit of income tax | C27: - | D27: - | E27: 337.44 | F27: 1026.14 | G27: 377.68 | H27: 737.02
B28: Interest on lease liability | C28: - | D28: 25.38 | E28: 32.71 | F28: 47.95 | G28: 44.92 | H28: 78.51
B29: Goodwill written off | C29: 2250.7 | D29: 0.34 | E29: 0 | F29: 0 | G29: 385.24 | H29: 0
B30: Operating profit before working capital changes | C30: =SUM(C6:C29) -> 7735.18 | D30: =SUM(D6:D29) -> 10545.72 | E30: =SUM(E6:E29) -> -277.72 | F30: =SUM(F6:F29) -> 3080.82 | G30: =SUM(G6:G29) -> 29843.04 | H30: =SUM(H6:H29) -> 21220.66
B32: Working capital adjustments:
B33: (Increase)/ Decrease in trade receivables | C33: 7032.26 | D33: -30883.07 | E33: 19887.35 | F33: -6595.27 | G33: -20531.48 | H33: -28991.02
B34: (Increase)/ Decrease in inventories | C34: -3049.51 | D34: -7814.92 | E34: -28440.32 | F34: -57670.04 | G34: 26177.99 | H34: -5500.3
B35: (Increase)/ Decrease in financial asset | C35: -796.03 | D35: -480.62 | E35: 299.69 | F35: 1339.11 | G35: -12929.75 | H35: 11334.27
B36: (Increase)/ Decrease in other asset | C36: -3796.27 | D36: -13039.23 | E36: -9430.83 | F36: -60559.12 | G36: 29556.15 | H36: 522.3
B37: Increase/ (Decrease) provisions | C37: 5502.31 | D37: 11789.46 | E37: 2993.23 | F37: 3689.17 | G37: 5320.74 | H37: 9568.57
B38: Increase/ (Decrease) in trade payable | C38: -7483.31 | D38: 18314.11 | E38: -7815.07 | F38: 41984.91 | G38: -6501.93 | H38: 9745.21
B39: Increase/ (Decrease) in other financial liability | C39: -862.27 | D39: 5334.55 | E39: 8543.64 | F39: 1899.44 | G39: 1621.1 | H39: 269.94
B40: Increase/ (Decrease) in other liability | C40: 2478.9 | D40: 5216.15 | E40: 7459.39 | F40: 17299.73 | G40: -6039.93 | H40: 5092.62
B41: Cash generated from operations | C41: =SUM(C33:C40,C30) -> 6761.26 | D41: =SUM(D33:D40,D30) -> -1017.85 | E41: =SUM(E33:E40,E30) -> -6780.64 | F41: =SUM(F33:F40,F30) -> -55531.25 | G41: =SUM(G33:G40,G30) -> 46515.93 | H41: =SUM(H33:H40,H30) -> 23262.25
B42: Income tax paid | C42: -34184.12 | D42: -33091.15 | E42: -45407.5 | F42: -49950.83 | G42: -32309.67 | H42: -47953.38
B43: Net cash inflow from operating activities | C43: =SUM(C41:C42) -> -27422.86 | D43: =SUM(D41:D42) -> -34109 | E43: =SUM(E41:E42) -> -52188.14 | F43: =SUM(F41:F42) -> -105482.08 | G43: =SUM(G41:G42) -> 14206.26 | H43: =SUM(H41:H42) -> -24691.13
A45: 2 | B45: Cash flow from Investing activities
...
