Workbook
Name IQ_CH: 110000
Name IQ_CQ: 5000
Name IQ_CY: 10000
Name IQ_DAILY: 500000
Name IQ_FH: 100000
Name IQ_FQ: 500
Name IQ_FY: 1000
Name IQ_LTM: 2000
Name IQ_MONTH: 15000
Name IQ_NTM: 6000
Name IQ_WEEK: 50000
Name IQ_YTD: 3000

Sheet Input Sheet
B3: Please provide the below inputs
B5: Name of the company | C5: Mankind Pharma Ltd
B7: WACC Inputs
B8: Country | C8: India
B9: Local Currency 10Y Government Bond Yield | C9: 0.0637
B10: =C8&"'s"&" Moodys Soveriegn Rating" -> India's Moodys Soveriegn Rating | C10: =VLOOKUP(C8,'Damodaran Data'!C5:E161,3,FALSE) -> Baa3
B11: Credit default spread as per Dr Damodaran | C11: =VLOOKUP(C8,'Damodaran Data'!C5:F161,4,FALSE) -> 0.0216
B12: Implied US Equity Risk Premium | C12: 0.0384
B13: Asset Beta | C13: =WACC!G77 -> 0.53918512
B14: Asset Beta Variation (+/-) | C14: 0.05
B15: Debt to Equity Ratio | C15: ='Assumptions Working'!I818 -> 0.59187826
B16: Debt to Capital (Gearing) | C16: ='Assumptions Working'!I819 -> 0.36800801
B17: Marginal Tax Rate | C17: 0.25
B18: Company Credit Rating Available ? | C18: No
B19: Company is Large Firm or Small Firm ? | C19: Large | G19: Large
B20: Provide Credit Rating | C20: A1/A+ | G20: Small
B21: Interest Coverage Ratio | C21: ='3StatementModel'!H30/('3StatementModel'!H34*-1) -> 4.7295296
B22: ICR based Corporate Default Spread | C22: =IF(C19="Large",VLOOKUP('Input Sheet'!C21,'Damodaran Data'!H6:K21,4,TRUE),VLOOKUP(C21,'Damodaran Data'!M6:P21,4,TRUE)) -> 0.0085
B23: Small Size Premium | C23: 0.056
B24: Asset Specific Risk Premium | C24: 0

Sheet ControlSheet 
B2: ='Input Sheet'!C5 -> Mankind Pharma Ltd
B3: Control Sheet | R3: Management Case
I4: Current Case | K4: 1 | R4: Base Case
R5: Worst Case
E8: Actual | J8: Explicit Forecast Period | O8: Maturity Period
B9: In INR Crores unless stated otherwise | E9: 2021 | F9: =E9+1 -> 2022 | G9: =F9+1 -> 2023 | H9: =G9+1 -> 2024 | I9: =H9+1 -> 2025 | J9: =I9+1 -> 2026 | K9: =J9+1 -> 2027 | L9: =K9+1 -> 2028 | M9: =L9+1 -> 2029 | ... S9: =R9+1 -> 2035
B11: Assumptions
A13: # | B13: Revenue
B15: Revenue - yoy % growth | K15: =J16-(($J$16-$N$16)/($N$9-$J$9)) -> 0.165
B16: Management Case | E16: ='Income Stmt'!E9 -> 0.059951905 | F16: ='Income Stmt'!F9 -> 0.2502703 | G16: ='Income Stmt'!G9 -> 0.12438104 | H16: ='Income Stmt'!H9 -> 0.18119364 | I16: ='Income Stmt'!I9 -> 0.18115784 | J16: 0.18 | K16: =J16-(($J$16-$N$16)/($N$9-$J$9)) -> 0.165 | L16: =K16-(($J$16-$N$16)/($N$9-$J$9)) -> 0.15 | M16: =L16-(($J$16-$N$16)/($N$9-$J$9)) -> 0.135 | N16: 0.12 | O16: 0.12 | P16: 0.12 | Q16: 0.12 | R16: 0.12 | S16: 0.12
B17: Base Case | E17: =E16 -> 0.059951905 | F17: =F16 -> 0.2502703 | G17: =G16 -> 0.12438104 | H17: =H16 -> 0.18119364 | I17: =I16 -> 0.18115784 | J17: 0.2 | K17: =J17-(($J$17-$N$17)/($N$9-$J$9)) -> 0.18 | L17: =K17-(($J$17-$N$17)/($N$9-$J$9)) -> 0.16 | M17: =L17-(($J$17-$N$17)/($N$9-$J$9)) -> 0.14 | N17: 0.12 | O17: 0.12 | P17: 0.12 | Q17: 0.12 | R17: 0.12 | S17: 0.12
B18: Down Case | E18: =E17 -> 0.059951905 | F18: =F17 -> 0.2502703 | G18: =G17 -> 0.12438104 | H18: =H17 -> 0.18119364 | I18: =I17 -> 0.18115784 | J18: 0.14 | K18: =J18-(($J$18-$N$18)/($N$9-$J$9)) -> 0.13 | L18: =K18-(($J$18-$N$18)/($N$9-$J$9)) -> 0.12 | M18: =L18-(($J$18-$N$18)/($N$9-$J$9)) -> 0.11 | N18: 0.1 | O18: 0.1 | P18: 0.1 | Q18: 0.1 | R18: 0.1 | S18: 0.1
B19: ="Current Case - "&CHOOSE($K$4,B16,B17,B18) -> Current Case - Management Case | J19: =CHOOSE($K$4,J16,J17,J18) -> 0.18 | K19: =CHOOSE($K$4,K16,K17,K18) -> 0.165 | L19: =CHOOSE($K$4,L16,L17,L18) -> 0.15 | M19: =CHOOSE($K$4,M16,M17,M18) -> 0.135 | N19: =CHOOSE($K$4,N16,N17,N18) -> 0.12 | O19: =CHOOSE($K$4,O16,O17,O18) -> 0.12 | P19: =CHOOSE($K$4,P16,P17,P18) -> 0.12 | Q19: =CHOOSE($K$4,Q16,Q17,Q18) -> 0.12 | ... S19: =CHOOSE($K$4,S16,S17,S18) -> 0.12
A21: # | B21: COGS
B23: Gross Margin%
B24: Management Case | E24: ='Income Stmt'!E21 -> 0.71390772 | F24: ='Income Stmt'!F21 -> 0.68878606 | G24: ='Income Stmt'!G21 -> 0.66699076 | H24: ='Income Stmt'!H21 -> 0.68942759 | I24: ='Income Stmt'!I21 -> 0.68419431 | J24: 0.66 | K24: =J24-(($J$24-$N$24)/($N$9-$J$9)) -> 0.666 | L24: =K24-(($J$24-$N$24)/($N$9-$J$9)) -> 0.672 | M24: =L24-(($J$24-$N$24)/($N$9-$J$9)) -> 0.678 | N24: 0.684 | O24: 0.684 | P24: 0.684 | Q24: 0.684 | R24: 0.684 | S24: 0.684
B25: Base Case | E25: =E24 -> 0.71390772 | F25: =F24 -> 0.68878606 | G25: =G24 -> 0.66699076 | H25: =H24 -> 0.68942759 | I25: =I24 -> 0.68419431 | J25: 0.68 | K25: =J25-(($J$25-$N$25)/($N$9-$J$9)) -> 0.665 | L25: =K25-(($J$25-$N$25)/($N$9-$J$9)) -> 0.65 | M25: =L25-(($J$25-$N$25)/($N$9-$J$9)) -> 0.635 | N25: 0.62 | O25: 0.62 | P25: 0.62 | Q25: 0.62 | R25: 0.62 | S25: 0.62
B26: Down Case | E26: =E25 -> 0.71390772 | F26: =F25 -> 0.68878606 | G26: =G25 -> 0.66699076 | H26: =H25 -> 0.68942759 | I26: =I25 -> 0.68419431 | J26: 0.65 | K26: =J26-(($J$26-$N$26)/($N$9-$J$9)) -> 0.604975 | L26: =K26-(($J$26-$N$26)/($N$9-$J$9)) -> 0.55995 | M26: =L26-(($J$26-$N$26)/($N$9-$J$9)) -> 0.514925 | N26: 0.4699 | O26: 0.4699 | P26: 0.4699 | Q26: 0.4699 | R26: 0.4699 | S26: 0.4699
B27: ="Current Case - "&CHOOSE($K$4,B24,B25,B26) -> Current Case - Management Case | J27: =CHOOSE($K$4,J24,J25,J26) -> 0.66 | K27: =CHOOSE($K$4,K24,K25,K26) -> 0.666 | L27: =CHOOSE($K$4,L24,L25,L26) -> 0.672 | M27: =CHOOSE($K$4,M24,M25,M26) -> 0.678 | N27: =CHOOSE($K$4,N24,N25,N26) -> 0.684 | O27: =CHOOSE($K$4,O24,O25,O26) -> 0.684 | P27: =CHOOSE($K$4,P24,P25,P26) -> 0.684 | Q27: =CHOOSE($K$4,Q24,Q25,Q26) -> 0.684 | ... S27: =CHOOSE($K$4,S24,S25,S26) -> 0.684
B29: Current Case - COGS % Sales | E29: =1-E26 -> 0.28609228 | F29: =1-F26 -> 0.31121394 | G29: =1-G26 -> 0.33300924 | H29: =1-H26 -> 0.31057241 | I29: =1-I26 -> 0.31580569 | J29: =1-J27 -> 0.34 | K29: =1-K27 -> 0.334 | L29: =1-L27 -> 0.328 | M29: =1-M27 -> 0.322 | N29: =1-N27 -> 0.316 | O29: =1-O27 -> 0.316 | P29: =1-P27 -> 0.316 | Q29: =1-Q27 -> 0.316 | ... S29: =1-S27 -> 0.316
A32: # | B32: Selling , General & Administration (SG&A)
B34: Employee Benefit Expense % Revenue
B35: Management Case | E35: ='Assumptions Working'!E355 -> 0.22747159 | F35: ='Assumptions Working'!F355 -> 0.20825914 | G35: ='Assumptions Working'!G355 -> 0.21926564 | H35: ='Assumptions Working'!H355 -> 0.22010156 | I35: ='Assumptions Working'!I355 -> 0.2205292 | J35: 0.22 | K35: 0.22 | L35: 0.22 | M35: 0.22 | N35: 0.22 | O35: 0.22 | P35: 0.22 | Q35: 0.22 | R35: 0.22 | S35: 0.22
B36: Base Case | E36: =E35 -> 0.22747159 | F36: =F35 -> 0.20825914 | G36: =G35 -> 0.21926564 | H36: =H35 -> 0.22010156 | I36: =I35 -> 0.2205292 | J36: 0.22 | K36: 0.22 | L36: 0.22 | M36: 0.22 | N36: 0.22 | O36: 0.22 | P36: 0.22 | Q36: 0.22 | R36: 0.22 | S36: 0.22
B37: Down Case | E37: =E36 -> 0.22747159 | F37: =F36 -> 0.20825914 | G37: =G36 -> 0.21926564 | H37: =H36 -> 0.22010156 | I37: =I36 -> 0.2205292 | J37: 0.22 | K37: 0.22 | L37: 0.22 | M37: 0.22 | N37: 0.22 | O37: 0.22 | P37: 0.22 | Q37: 0.22 | R37: 0.22 | S37: 0.22
B38: ="Current Case - "&CHOOSE($K$4,B35,B36,B37) -> Current Case - Management Case | J38: =CHOOSE($K$4,J35,J36,J37) -> 0.22 | K38: =CHOOSE($K$4,K35,K36,K37) -> 0.22 | L38: =CHOOSE($K$4,L35,L36,L37) -> 0.22 | M38: =CHOOSE($K$4,M35,M36,M37) -> 0.22 | N38: =CHOOSE($K$4,N35,N36,N37) -> 0.22 | O38: =CHOOSE($K$4,O35,O36,O37) -> 0.22 | P38: =CHOOSE($K$4,P35,P36,P37) -> 0.22 | Q38: =CHOOSE($K$4,Q35,Q36,Q37) -> 0.22 | ... S38: =CHOOSE($K$4,S35,S36,S37) -> 0.22
B40: Advertising & Sales Promotion Expense % Revenue
B41: Management Case | E41: ='Assumptions Working'!E358 -> 0.061977235 | F41: ='Assumptions Working'!F358 -> 0.058029532 | G41: ='Assumptions Working'!G358 -> 0.042707407 | H41: ='Assumptions Working'!H358 -> 0.058433031 | I41: ='Assumptions Working'!I358 -> 0.061849758 | J41: 0.058 | K41: 0.058 | L41: 0.058 | M41: 0.058 | N41: 0.058 | O41: 0.058 | P41: 0.058 | Q41: 0.058 | R41: 0.058 | S41: 0.058
B42: Base Case | E42: =E41 -> 0.061977235 | F42: =F41 -> 0.058029532 | G42: =G41 -> 0.042707407 | H42: =H41 -> 0.058433031 | I42: =I41 -> 0.061849758 | J42: 0.058 | K42: 0.058 | L42: 0.058 | M42: 0.058 | N42: 0.058 | O42: 0.058 | P42: 0.058 | Q42: 0.058 | R42: 0.058 | S42: 0.058
B43: Down Case | E43: =E42 -> 0.061977235 | F43: =F42 -> 0.058029532 | G43: =G42 -> 0.042707407 | H43: =H42 -> 0.058433031 | I43: =I42 -> 0.061849758 | J43: 0.058 | K43: 0.058 | L43: 0.058 | M43: 0.058 | N43: 0.058 | O43: 0.058 | P43: 0.058 | Q43: 0.058 | R43: 0.058 | S43: 0.058
B44: ="Current Case - "&CHOOSE($K$4,B41,B42,B43) -> Current Case - Management Case | J44: =CHOOSE($K$4,J41,J42,J43) -> 0.058 | K44: =CHOOSE($K$4,K41,K42,K43) -> 0.058 | L44: =CHOOSE($K$4,L41,L42,L43) -> 0.058 | M44: =CHOOSE($K$4,M41,M42,M43) -> 0.058 | N44: =CHOOSE($K$4,N41,N42,N43) -> 0.058 | O44: =CHOOSE($K$4,O41,O42,O43) -> 0.058 | P44: =CHOOSE($K$4,P41,P42,P43) -> 0.058 | Q44: =CHOOSE($K$4,Q41,Q42,Q43) -> 0.058 | ... S44: =CHOOSE($K$4,S41,S42,S43) -> 0.058
B46: Travelling and conveyance Expense % Revenue
B47: Management Case | E47: ='Assumptions Working'!E361 -> 0.043445441 | F47: ='Assumptions Working'!F361 -> 0.046020364 | G47: ='Assumptions Working'!G361 -> 0.056694748 | H47: ='Assumptions Working'!H361 -> 0.036614267 | I47: ='Assumptions Working'!I361 -> 0.037765217 | J47: 0.046 | K47: 0.046 | L47: 0.046 | M47: 0.046 | N47: 0.046 | O47: 0.046 | P47: 0.046 | Q47: 0.046 | R47: 0.046 | S47: 0.046
B48: Base Case | E48: =E47 -> 0.043445441 | F48: =F47 -> 0.046020364 | G48: =G47 -> 0.056694748 | H48: =H47 -> 0.036614267 | I48: =I47 -> 0.037765217 | J48: 0.046 | K48: 0.046 | L48: 0.046 | M48: 0.046 | N48: 0.046 | O48: 0.046 | P48: 0.046 | Q48: 0.046 | R48: 0.046 | S48: 0.046
B49: Down Case | E49: =E48 -> 0.043445441 | F49: =F48 -> 0.046020364 | G49: =G48 -> 0.056694748 | H49: =H48 -> 0.036614267 | I49: =I48 -> 0.037765217 | J49: 0.046 | K49: 0.046 | L49: 0.046 | M49: 0.046 | N49: 0.046 | O49: 0.046 | P49: 0.046 | Q49: 0.046 | R49: 0.046 | S49: 0.046
B50: ="Current Case - "&CHOOSE($K$4,B47,B48,B49) -> Current Case - Management Case | J50: =CHOOSE($K$4,J47,J48,J49) -> 0.046 | K50: =CHOOSE($K$4,K47,K48,K49) -> 0.046 | L50: =CHOOSE($K$4,L47,L48,L49) -> 0.046 | M50: =CHOOSE($K$4,M47,M48,M49) -> 0.046 | N50: =CHOOSE($K$4,N47,N48,N49) -> 0.046 | O50: =CHOOSE($K$4,O47,O48,O49) -> 0.046 | P50: =CHOOSE($K$4,P47,P48,P49) -> 0.046 | Q50: =CHOOSE($K$4,Q47,Q48,Q49) -> 0.046 | ... S50: =CHOOSE($K$4,S47,S48,S49) -> 0.046
B52: Other Operating Expense % Revenue
B53: Management Case | E53: ='Assumptions Working'!E364 -> 0.059441846 | F53: ='Assumptions Working'!F364 -> 0.065664253 | G53: ='Assumptions Working'!G364 -> 0.070768529 | H53: ='Assumptions Working'!H364 -> 0.077786834 | I53: ='Assumptions Working'!I364 -> 0.087900385 | J53: 0.066 | K53: 0.066 | L53: 0.066 | M53: 0.066 | N53: 0.066 | O53: 0.066 | P53: 0.066 | Q53: 0.066 | R53: 0.066 | S53: 0.066
B54: Base Case | E54: =E53 -> 0.059441846 | F54: =F53 -> 0.065664253 | G54: =G53 -> 0.070768529 | H54: =H53 -> 0.077786834 | I54: =I53 -> 0.087900385 | J54: 0.066 | K54: 0.066 | L54: 0.066 | M54: 0.066 | N54: 0.066 | O54: 0.066 | P54: 0.066 | Q54: 0.066 | R54: 0.066 | S54: 0.066
B55: Down Case | E55: =E54 -> 0.059441846 | F55: =F54 -> 0.065664253 | G55: =G54 -> 0.070768529 | H55: =H54 -> 0.077786834 | I55: =I54 -> 0.087900385 | J55: 0.066 | K55: 0.066 | L55: 0.066 | M55: 0.066 | N55: 0.066 | O55: 0.066 | P55: 0.066 | Q55: 0.066 | R55: 0.066 | S55: 0.066
...

Sheet Schedules
B2: ='Input Sheet'!C5 -> Mankind Pharma Ltd
B3: Schedules
I4: Current Case | K4: 1
E8: Actual | J8: Explicit Forecast Period | O8: Maturity Period
B9: In INR Crores unless stated otherwise | E9: ='ControlSheet '!E9 -> 2021 | F9: ='ControlSheet '!F9 -> 2022 | G9: ='ControlSheet '!G9 -> 2023 | H9: ='ControlSheet '!H9 -> 2024 | I9: ='ControlSheet '!I9 -> 2025 | J9: ='ControlSheet '!J9 -> 2026 | K9: ='ControlSheet '!K9 -> 2027 | L9: ='ControlSheet '!L9 -> 2028 | ... S9: ='ControlSheet '!S9 -> 2035
A11: # | B11: Revenue Schedules
B13: Revenue | E13: ='Income Stmt'!E7 -> 6223.8982 | F13: ='Income Stmt'!F7 -> 7781.5551 | G13: ='Income Stmt'!G7 -> 8749.433 | H13: ='Income Stmt'!H7 -> 10334.775 | I13: ='Income Stmt'!I7 -> 12207 | J13: =I13*(1+J15) -> 14404.26 | K13: =J13*(1+K15) -> 16780.963 | L13: =K13*(1+L15) -> 19298.107 | M13: =L13*(1+M15) -> 21903.352 | N13: =M13*(1+N15) -> 24531.754 | O13: =N13*(1+O15) -> 27475.565 | P13: =O13*(1+P15) -> 30772.632 | Q13: =P13*(1+Q15) -> 34465.348 | ... S13: =R13*(1+S15) -> 43233.333
B15: Growth YoY% | F15: =F13/E13-1 -> 0.2502703 | G15: =G13/F13-1 -> 0.12438104 | H15: =H13/G13-1 -> 0.18119364 | I15: =I13/H13-1 -> 0.18115784 | J15: ='ControlSheet '!J19 -> 0.18 | K15: ='ControlSheet '!K19 -> 0.165 | L15: ='ControlSheet '!L19 -> 0.15 | M15: ='ControlSheet '!M19 -> 0.135 | N15: ='ControlSheet '!N19 -> 0.12 | O15: ='ControlSheet '!O19 -> 0.12 | P15: ='ControlSheet '!P19 -> 0.12 | Q15: ='ControlSheet '!Q19 -> 0.12 | ... S15: ='ControlSheet '!S19 -> 0.12
A17: # | B17: COGS Schedules
B20: COGS | E20: ='Income Stmt'!E18*-1 -> 1780.6092 | F20: ='Income Stmt'!F18*-1 -> 2421.7284 | G20: ='Income Stmt'!G18*-1 -> 2913.642 | H20: ='Income Stmt'!H18*-1 -> 3209.6959 | I20: ='Income Stmt'!I18*-1 -> 3855.04 | J20: =J13*J22 -> 4897.4484 | K20: =K13*K22 -> 5604.8416 | L20: =L13*L22 -> 6329.7792 | M20: =M13*M22 -> 7052.8793 | N20: =N13*N22 -> 7752.0343 | O20: =O13*O22 -> 8682.2784 | P20: =P13*P22 -> 9724.1518 | Q20: =Q13*Q22 -> 10891.05 | ... S20: =S13*S22 -> 13661.733
B22: COGS % Sales | E22: =E20/E13 -> 0.28609228 | F22: =F20/F13 -> 0.31121394 | G22: =G20/G13 -> 0.33300924 | H22: =H20/H13 -> 0.31057241 | I22: =I20/I13 -> 0.31580569 | J22: ='ControlSheet '!J29 -> 0.34 | K22: ='ControlSheet '!K29 -> 0.334 | L22: ='ControlSheet '!L29 -> 0.328 | M22: ='ControlSheet '!M29 -> 0.322 | N22: ='ControlSheet '!N29 -> 0.316 | O22: ='ControlSheet '!O29 -> 0.316 | P22: ='ControlSheet '!P29 -> 0.316 | Q22: ='ControlSheet '!Q29 -> 0.316 | ... S22: ='ControlSheet '!S29 -> 0.316
A24: # | B24: SG&A (Excluding Depreciation & Interest Expenses) Schedule
B26: Employee Benefit Expense
B28: =B26 -> Employee Benefit Expense | E28: ='Assumptions Working'!E354 -> 1415.76 | F28: ='Assumptions Working'!F354 -> 1620.58 | G28: ='Assumptions Working'!G354 -> 1918.45 | H28: ='Assumptions Working'!H354 -> 2274.7 | I28: ='Assumptions Working'!I354 -> 2692 | J28: =J$13*J29 -> 3168.9372 | K28: =K$13*K29 -> 3691.8118 | L28: =L$13*L29 -> 4245.5836 | M28: =M$13*M29 -> 4818.7374 | N28: =N$13*N29 -> 5396.9859 | O28: =O$13*O29 -> 6044.6242 | P28: =P$13*P29 -> 6769.9791 | Q28: =Q$13*Q29 -> 7582.3766 | ... S28: =S$13*S29 -> 9511.3332
B29: =B28&" % Revenue" -> Employee Benefit Expense % Revenue | E29: ='Assumptions Working'!E355 -> 0.22747159 | F29: ='Assumptions Working'!F355 -> 0.20825914 | G29: ='Assumptions Working'!G355 -> 0.21926564 | H29: ='Assumptions Working'!H355 -> 0.22010156 | I29: ='Assumptions Working'!I355 -> 0.2205292 | J29: ='ControlSheet '!J38 -> 0.22 | K29: ='ControlSheet '!K38 -> 0.22 | L29: ='ControlSheet '!L38 -> 0.22 | M29: ='ControlSheet '!M38 -> 0.22 | N29: ='ControlSheet '!N38 -> 0.22 | O29: ='ControlSheet '!O38 -> 0.22 | P29: ='ControlSheet '!P38 -> 0.22 | Q29: ='ControlSheet '!Q38 -> 0.22 | ... S29: ='ControlSheet '!S38 -> 0.22
B31: Advertising & Sales Promotion Expense
B33: =B31 -> Advertising & Sales Promotion Expense | E33: ='Assumptions Working'!E357 -> 385.74 | F33: ='Assumptions Working'!F357 -> 451.56 | G33: ='Assumptions Working'!G357 -> 373.6656 | H33: ='Assumptions Working'!H357 -> 603.8922 | I33: ='Assumptions Working'!I357 -> 755 | J33: =J$13*J34 -> 835.44708 | K33: =K$13*K34 -> 973.29585 | L33: =L$13*L34 -> 1119.2902 | M33: =M$13*M34 -> 1270.3944 | N33: =N$13*N34 -> 1422.8417 | O33: =O$13*O34 -> 1593.5827 | P33: =P$13*P34 -> 1784.8127 | Q33: =Q$13*Q34 -> 1998.9902 | ... S33: =S$13*S34 -> 2507.5333
B34: =B33&" % Revenue" -> Advertising & Sales Promotion Expense % Revenue | E34: ='Assumptions Working'!E358 -> 0.061977235 | F34: ='Assumptions Working'!F358 -> 0.058029532 | G34: ='Assumptions Working'!G358 -> 0.042707407 | H34: ='Assumptions Working'!H358 -> 0.058433031 | I34: ='Assumptions Working'!I358 -> 0.061849758 | J34: ='ControlSheet '!J44 -> 0.058 | K34: ='ControlSheet '!K44 -> 0.058 | L34: ='ControlSheet '!L44 -> 0.058 | M34: ='ControlSheet '!M44 -> 0.058 | N34: ='ControlSheet '!N44 -> 0.058 | O34: ='ControlSheet '!O44 -> 0.058 | P34: ='ControlSheet '!P44 -> 0.058 | Q34: ='ControlSheet '!Q44 -> 0.058 | ... S34: ='ControlSheet '!S44 -> 0.058
B36: Travelling and conveyance Expense
B38: =B36 -> Travelling and conveyance Expense | E38: ='Assumptions Working'!E360 -> 270.4 | F38: ='Assumptions Working'!F360 -> 358.11 | G38: ='Assumptions Working'!G360 -> 496.0469 | H38: ='Assumptions Working'!H360 -> 378.4002 | I38: ='Assumptions Working'!I360 -> 461 | J38: =J$13*J39 -> 662.59596 | K38: =K$13*K39 -> 771.92429 | L38: =L$13*L39 -> 887.71294 | M38: =M$13*M39 -> 1007.5542 | N38: =N$13*N39 -> 1128.4607 | O38: =O$13*O39 -> 1263.876 | P38: =P$13*P39 -> 1415.5411 | Q38: =Q$13*Q39 -> 1585.406 | ... S38: =S$13*S39 -> 1988.7333
B39: =B38&" % Revenue" -> Travelling and conveyance Expense % Revenue | E39: ='Assumptions Working'!E361 -> 0.043445441 | F39: ='Assumptions Working'!F361 -> 0.046020364 | G39: ='Assumptions Working'!G361 -> 0.056694748 | H39: ='Assumptions Working'!H361 -> 0.036614267 | I39: ='Assumptions Working'!I361 -> 0.037765217 | J39: ='ControlSheet '!J50 -> 0.046 | K39: ='ControlSheet '!K50 -> 0.046 | L39: ='ControlSheet '!L50 -> 0.046 | M39: ='ControlSheet '!M50 -> 0.046 | N39: ='ControlSheet '!N50 -> 0.046 | O39: ='ControlSheet '!O50 -> 0.046 | P39: ='ControlSheet '!P50 -> 0.046 | Q39: ='ControlSheet '!Q50 -> 0.046 | ... S39: ='ControlSheet '!S50 -> 0.046
B41: Other Operating Expense
B43: =B41 -> Other Operating Expense | E43: ='Assumptions Working'!E363 -> 369.96 | F43: ='Assumptions Working'!F363 -> 510.97 | G43: ='Assumptions Working'!G363 -> 619.1845 | H43: ='Assumptions Working'!H363 -> 803.9094 | I43: ='Assumptions Working'!I363 -> 1073 | J43: =J$13*J44 -> 950.68116 | K43: =K$13*K44 -> 1107.5436 | L43: =L$13*L44 -> 1273.6751 | M43: =M$13*M44 -> 1445.6212 | N43: =N$13*N44 -> 1619.0958 | O43: =O$13*O44 -> 1813.3873 | P43: =P$13*P44 -> 2030.9937 | Q43: =Q$13*Q44 -> 2274.713 | ... S43: =S$13*S44 -> 2853.4
B44: =B43&" % Revenue" -> Other Operating Expense % Revenue | E44: ='Assumptions Working'!E364 -> 0.059441846 | F44: ='Assumptions Working'!F364 -> 0.065664253 | G44: ='Assumptions Working'!G364 -> 0.070768529 | H44: ='Assumptions Working'!H364 -> 0.077786834 | I44: ='Assumptions Working'!I364 -> 0.087900385 | J44: ='ControlSheet '!J56 -> 0.066 | K44: ='ControlSheet '!K56 -> 0.066 | L44: ='ControlSheet '!L56 -> 0.066 | M44: ='ControlSheet '!M56 -> 0.066 | N44: ='ControlSheet '!N56 -> 0.066 | O44: ='ControlSheet '!O56 -> 0.066 | P44: ='ControlSheet '!P56 -> 0.066 | Q44: ='ControlSheet '!Q56 -> 0.066 | ... S44: ='ControlSheet '!S56 -> 0.066
B46: Other Misc SG&A Expenses
B48: =B46 -> Other Misc SG&A Expenses | E48: ='Assumptions Working'!E366 -> 343.8362 | F48: ='Assumptions Working'!F366 -> 429.2405 | G48: ='Assumptions Working'!G366 -> 527.7859 | H48: ='Assumptions Working'!H366 -> 529.0736 | I48: ='Assumptions Working'!I366 -> 719.1 | J48: =J$13*J49 -> 792.2343 | K48: =K$13*K49 -> 922.95296 | L48: =L$13*L49 -> 1061.3959 | M48: =M$13*M49 -> 1204.6844 | N48: =N$13*N49 -> 1349.2465 | O48: =O$13*O49 -> 1511.156 | P48: =P$13*P49 -> 1692.4948 | Q48: =Q$13*Q49 -> 1895.5941 | ... S48: =S$13*S49 -> 2377.8333
B49: =B48&" % Revenue" -> Other Misc SG&A Expenses % Revenue | E49: ='Assumptions Working'!E367 -> 0.055244509 | F49: ='Assumptions Working'!F367 -> 0.055161275 | G49: ='Assumptions Working'!G367 -> 0.060322297 | H49: ='Assumptions Working'!H367 -> 0.051193531 | I49: ='Assumptions Working'!I367 -> 0.058908823 | J49: ='ControlSheet '!J62 -> 0.055 | K49: ='ControlSheet '!K62 -> 0.055 | L49: ='ControlSheet '!L62 -> 0.055 | M49: ='ControlSheet '!M62 -> 0.055 | N49: ='ControlSheet '!N62 -> 0.055 | O49: ='ControlSheet '!O62 -> 0.055 | P49: ='ControlSheet '!P62 -> 0.055 | Q49: ='ControlSheet '!Q62 -> 0.055 | ... S49: ='ControlSheet '!S62 -> 0.055
B50: ="Total " &B46 -> Total Other Misc SG&A Expenses | J50: =SUM(J48:J49) -> 792.2893 | K50: =SUM(K48:K49) -> 923.00796 | L50: =SUM(L48:L49) -> 1061.4509 | M50: =SUM(M48:M49) -> 1204.7394 | N50: =SUM(N48:N49) -> 1349.3015 | O50: =SUM(O48:O49) -> 1511.211 | P50: =SUM(P48:P49) -> 1692.5498 | Q50: =SUM(Q48:Q49) -> 1895.6491 | ... S50: =SUM(S48:S49) -> 2377.8883
B52: Total SG&A ( Excluding Depreciation & Interest Expense) | E52: =E48+E43+E38+E33+E28 -> 2785.6962 | F52: =F48+F43+F38+F33+F28 -> 3370.4605 | G52: =G48+G43+G38+G33+G28 -> 3935.1329 | H52: =H48+H43+H38+H33+H28 -> 4589.9754 | I52: =I48+I43+I38+I33+I28 -> 5700.1 | J52: =J48+J43+J38+J33+J28 -> 6409.8957 | K52: =K48+K43+K38+K33+K28 -> 7467.5285 | L52: =L48+L43+L38+L33+L28 -> 8587.6578 | ... S52: =S48+S43+S38+S33+S28 -> 19238.833
B53: Total SG&A % Sales | E53: =E52/E13 -> 0.44758062 | F53: =F52/F13 -> 0.43313457 | G53: =G52/G13 -> 0.44975862 | H53: =H52/H13 -> 0.44412922 | I53: =I52/I13 -> 0.46695339 | J53: =J52/J13 -> 0.445 | K53: =K52/K13 -> 0.445 | L53: =L52/L13 -> 0.445 | ... S53: =S52/S13 -> 0.445
A55: # | B55: Non Current Asset Schedule
B57: Property , Plants & Equipments
B59: Opening PP&E | J59: ='Balance Sheet'!I7 -> 2740.6305 | K59: =J62 -> 3216.7203 | L59: =K62 -> 3712.1631 | M59: =L62 -> 4363.6545 | N59: =M62 -> 4987.4966 | O59: =N62 -> 5559.1252 | P59: =O62 -> 6179.3793 | Q59: =P62 -> 6854.0939 | R59: =Q62 -> 7589.8042 | S59: =R62 -> 8393.8298
B60: Add: Capex During the Year | J60: ='Assumptions Working'!C685 -> 652.91502 | K60: ='Assumptions Working'!D685 -> 717.086 | L60: =(L13-K13)*'Assumptions Working'!E686 -> 931.34344 | M60: =(M13-L13)*'Assumptions Working'!F686 -> 963.94046 | N60: =(N13-M13)*'Assumptions Working'!G686 -> 972.50882 | O60: =(O13-N13)*'Assumptions Working'!$G$686 -> 1089.2099 | P60: =(P13-O13)*'Assumptions Working'!$G$686 -> 1219.9151 | Q60: =(Q13-P13)*'Assumptions Working'!$G$686 -> 1366.3049 | R60: =(R13-Q13)*'Assumptions Working'!$G$686 -> 1530.2615 | S60: =(S13-R13)*'Assumptions Working'!$G$686 -> 1713.8928
B61: Less: Depreciation | I61: =('Income Stmt'!I37*-1)/(SUM('Balance Sheet'!I7,'Balance Sheet'!I9,'Balance Sheet'!I11))*'Balance Sheet'!I7 -> 136.01806 | J61: =I61+(J60/$C$117) -> 176.82525 | K61: =J61+(K60/$C$117) -> 221.64313 | L61: =K61+(L60/$C$117) -> 279.85209 | M61: =L61+(M60/$C$117) -> 340.09837 | N61: =M61+(N60/$C$117) -> 400.88017 | O61: =N61+(O60/$C$117) -> 468.95579 | P61: =O61+(P60/$C$117) -> 545.20048 | Q61: =P61+(Q60/$C$117) -> 630.59454 | ... S61: =R61+(S60/$C$117) -> 833.35418
B62: Closing PP&E | I62: 2741 | J62: =J59+J60-J61 -> 3216.7203 | K62: =K59+K60-K61 -> 3712.1631 | L62: =L59+L60-L61 -> 4363.6545 | M62: =M59+M60-M61 -> 4987.4966 | N62: =N59+N60-N61 -> 5559.1252 | O62: =O59+O60-O61 -> 6179.3793 | P62: =P59+P60-P61 -> 6854.0939 | Q62: =Q59+Q60-Q61 -> 7589.8042 | ... S62: =S59+S60-S61 -> 9274.3685
B63: YoY Growth % | J63: =J62/I62-1 -> 0.17355719 | K63: =K62/J62-1 -> 0.15402112 | L63: =L62/K62-1 -> 0.17550181 | M63: =M62/L62-1 -> 0.14296322 | N63: =N62/M62-1 -> 0.11461234 | O63: =O62/N62-1 -> 0.11157405 | P63: =P62/O62-1 -> 0.10918808 | Q63: =Q62/P62-1 -> 0.10733882 | ... S63: =S62/R62-1 -> 0.10490309
B65: Right of Use Asset
B66: =B65 -> Right of Use Asset | E66: ='Balance Sheet'!E9 -> 0 | F66: ='Balance Sheet'!F9 -> 67.3571 | G66: ='Balance Sheet'!G9 -> 114.3647 | H66: ='Balance Sheet'!H9 -> 119.0613 | I66: ='Balance Sheet'!I9 -> 167.25 | J66: =I66*(1+J72) -> 167.25 | K66: =J69 -> 158.94935 | L66: =K69 -> 150.6487 | M66: =L69 -> 142.34804 | N66: =M69 -> 134.04739 | O66: =N69 -> 125.74674 | P66: =O69 -> 117.44609 | Q66: =P69 -> 109.14543 | R66: =Q69 -> 100.84478 | S66: =R69 -> 92.544128
B67: Addition During the Year | J67: =I66*(J72) -> 0 | K67: =J66*(K72) -> 0 | L67: =K66*(L72) -> 0 | M67: =L66*(M72) -> 0 | N67: =M66*(N72) -> 0 | O67: =N66*(O72) -> 0 | P67: =O66*(P72) -> 0 | Q67: =P66*(Q72) -> 0 | ... S67: =R66*(S72) -> 0
...

Sheet 3StatementModel
B2: ='Input Sheet'!C5 -> Mankind Pharma Ltd
B3: 3 Statement Model
H4: Current Case | J4: 1
T7: CAGR
D8: Actual | I8: Explicit Forecast Period | N8: Maturity Period | T8: 5 Years | U8: 3 Years
B9: In INR Crores unless stated otherwise | D9: ='ControlSheet '!E9 -> 2021 | E9: ='ControlSheet '!F9 -> 2022 | F9: ='ControlSheet '!G9 -> 2023 | G9: ='ControlSheet '!H9 -> 2024 | H9: ='ControlSheet '!I9 -> 2025 | I9: ='ControlSheet '!J9 -> 2026 | J9: ='ControlSheet '!K9 -> 2027 | K9: ='ControlSheet '!L9 -> 2028 | ... R9: ='ControlSheet '!S9 -> 2035
A11: # | B11: Income Statement
B13: Revenue | D13: =Schedules!E13 -> 6223.8982 | E13: =Schedules!F13 -> 7781.5551 | F13: =Schedules!G13 -> 8749.433 | G13: =Schedules!H13 -> 10334.775 | H13: =Schedules!I13 -> 12207 | I13: =Schedules!J13 -> 14404.26 | J13: =Schedules!K13 -> 16780.963 | K13: =Schedules!L13 -> 19298.107 | ... R13: =Schedules!S13 -> 43233.333 | T13: =_xlfn.RRI($M$9-$H$9,H13,M13) -> 0.14980431 | U13: =_xlfn.RRI($M$9-$J$9,J13,M13) -> 0.13493392
B14: Less: Cost of Goods Sold | D14: =Schedules!E20*-1 -> -1780.6092 | E14: =Schedules!F20*-1 -> -2421.7284 | F14: =Schedules!G20*-1 -> -2913.642 | G14: =Schedules!H20*-1 -> -3209.6959 | H14: =Schedules!I20*-1 -> -3855.04 | I14: =Schedules!J20*-1 -> -4897.4484 | J14: =Schedules!K20*-1 -> -5604.8416 | K14: =Schedules!L20*-1 -> -6329.7792 | ... R14: =Schedules!S20*-1 -> -13661.733 | T14: =_xlfn.RRI($M$9-$H$9,H14,M14) -> 0.14994577 | U14: =_xlfn.RRI($M$9-$J$9,J14,M14) -> 0.11416825
B15: Gross Profit | D15: =D13+D14 -> 4443.289 | E15: =E13+E14 -> 5359.8267 | F15: =F13+F14 -> 5835.791 | G15: =G13+G14 -> 7125.0787 | H15: =H13+H14 -> 8351.96 | I15: =I13+I14 -> 9506.8116 | J15: =J13+J14 -> 11176.121 | K15: =K13+K14 -> 12968.328 | ... R15: =R13+R14 -> 29571.6 | T15: =_xlfn.RRI($M$9-$H$9,H15,M15) -> 0.14973899 | U15: =_xlfn.RRI($M$9-$J$9,J15,M15) -> 0.14506779
B17: Gross Margin | D17: =D15/D13 -> 0.71390772 | E17: =E15/E13 -> 0.68878606 | F17: =F15/F13 -> 0.66699076 | G17: =G15/G13 -> 0.68942759 | H17: =H15/H13 -> 0.68419431 | I17: =I15/I13 -> 0.66 | J17: =J15/J13 -> 0.666 | K17: =K15/K13 -> 0.672 | ... R17: =R15/R13 -> 0.684
B19: Less: SG&A Expenses (Excluding Depreciation & Interest) | D19: =SUM(D20:D24) -> 2785.6962 | E19: =SUM(E20:E24) -> 3370.4605 | F19: =SUM(F20:F24) -> 3935.1329 | G19: =SUM(G20:G24) -> 4589.9754 | H19: =SUM(H20:H24) -> 5700.1 | I19: =SUM(I20:I24) -> 6409.8957 | J19: =SUM(J20:J24) -> 7467.5285 | K19: =SUM(K20:K24) -> 8587.6578 | ... R19: =SUM(R20:R24) -> 19238.833
B20: =Schedules!B26 -> Employee Benefit Expense | D20: =Schedules!E28 -> 1415.76 | E20: =Schedules!F28 -> 1620.58 | F20: =Schedules!G28 -> 1918.45 | G20: =Schedules!H28 -> 2274.7 | H20: =Schedules!I28 -> 2692 | I20: =Schedules!J28 -> 3168.9372 | J20: =Schedules!K28 -> 3691.8118 | K20: =Schedules!L28 -> 4245.5836 | ... R20: =Schedules!S28 -> 9511.3332 | T20: =_xlfn.RRI($M$9-$H$9,H20,M20) -> 0.14925194 | U20: =_xlfn.RRI($M$9-$J$9,J20,M20) -> 0.13493392
B21: =Schedules!B31 -> Advertising & Sales Promotion Expense | D21: =Schedules!E33 -> 385.74 | E21: =Schedules!F33 -> 451.56 | F21: =Schedules!G33 -> 373.6656 | G21: =Schedules!H33 -> 603.8922 | H21: =Schedules!I33 -> 755 | I21: =Schedules!J33 -> 835.44708 | J21: =Schedules!K33 -> 973.29585 | K21: =Schedules!L33 -> 1119.2902 | ... R21: =Schedules!S33 -> 2507.5333 | T21: =_xlfn.RRI($M$9-$H$9,H21,M21) -> 0.1351204 | U21: =_xlfn.RRI($M$9-$J$9,J21,M21) -> 0.13493392
B22: =Schedules!B36 -> Travelling and conveyance Expense | D22: =Schedules!E38 -> 270.4 | E22: =Schedules!F38 -> 358.11 | F22: =Schedules!G38 -> 496.0469 | G22: =Schedules!H38 -> 378.4002 | H22: =Schedules!I38 -> 461 | I22: =Schedules!J38 -> 662.59596 | J22: =Schedules!K38 -> 771.92429 | K22: =Schedules!L38 -> 887.71294 | ... R22: =Schedules!S38 -> 1988.7333 | T22: =_xlfn.RRI($M$9-$H$9,H22,M22) -> 0.19607139 | U22: =_xlfn.RRI($M$9-$J$9,J22,M22) -> 0.13493392
B23: =Schedules!B41 -> Other Operating Expense | D23: =Schedules!E43 -> 369.96 | E23: =Schedules!F43 -> 510.97 | F23: =Schedules!G43 -> 619.1845 | G23: =Schedules!H43 -> 803.9094 | H23: =Schedules!I43 -> 1073 | I23: =Schedules!J43 -> 950.68116 | J23: =Schedules!K43 -> 1107.5436 | K23: =Schedules!L43 -> 1273.6751 | ... R23: =Schedules!S43 -> 2853.4 | T23: =_xlfn.RRI($M$9-$H$9,H23,M23) -> 0.085761813 | U23: =_xlfn.RRI($M$9-$J$9,J23,M23) -> 0.13493392
B24: =Schedules!B46 -> Other Misc SG&A Expenses | D24: =Schedules!E48 -> 343.8362 | E24: =Schedules!F48 -> 429.2405 | F24: =Schedules!G48 -> 527.7859 | G24: =Schedules!H48 -> 529.0736 | H24: =Schedules!I48 -> 719.1 | I24: =Schedules!J48 -> 792.2343 | J24: =Schedules!K48 -> 922.95296 | K24: =Schedules!L48 -> 1061.3959 | ... R24: =Schedules!S48 -> 2377.8333 | T24: =_xlfn.RRI($M$9-$H$9,H24,M24) -> 0.13412363 | U24: =_xlfn.RRI($M$9-$J$9,J24,M24) -> 0.13493392
B25: EBITDA | D25: =D15-SUM(D20:D24) -> 1657.5928 | E25: =E15-SUM(E20:E24) -> 1989.3662 | F25: =F15-SUM(F20:F24) -> 1900.6581 | G25: =G15-SUM(G20:G24) -> 2535.1033 | H25: =H15-SUM(H20:H24) -> 2651.86 | I25: =I15-SUM(I20:I24) -> 3096.9159 | J25: =J15-SUM(J20:J24) -> 3708.5928 | K25: =K15-SUM(K20:K24) -> 4380.6704 | ... R25: =R15-SUM(R20:R24) -> 10332.767 | T25: =_xlfn.RRI($M$9-$H$9,H25,M25) -> 0.17196646 | U25: =_xlfn.RRI($M$9-$J$9,J25,M25) -> 0.16494597
B27: EBITDA Margin | D27: =D25/D13 -> 0.26632711 | E27: =E25/E13 -> 0.2556515 | F27: =F25/F13 -> 0.21723215 | G27: =G25/G13 -> 0.24529836 | H27: =H25/H13 -> 0.21724093 | I27: =I25/I13 -> 0.215 | J27: =J25/J13 -> 0.221 | K27: =K25/K13 -> 0.227 | ... R27: =R25/R13 -> 0.239
B29: Less: Depreciation | D29: ='Income Stmt'!E37*-1 -> 118.9703 | E29: ='Income Stmt'!F37*-1 -> 166.6192 | F29: ='Income Stmt'!G37*-1 -> 325.9195 | G29: ='Income Stmt'!H37*-1 -> 398.2537 | H29: ='Income Stmt'!I37*-1 -> 621 | I29: =Schedules!J119 -> 661.80719 | J29: =Schedules!K119 -> 706.62506 | K29: =Schedules!L119 -> 764.83403 | L29: =Schedules!M119 -> 825.08031 | M29: =Schedules!N119 -> 885.86211 | N29: =Schedules!O119 -> 953.93773 | O29: =Schedules!P119 -> 1030.1824 | P29: =Schedules!Q119 -> 1115.5765 | ... R29: =Schedules!S119 -> 1318.3361 | T29: =_xlfn.RRI($M$9-$H$9,H29,M29) -> 0.07363066 | U29: =_xlfn.RRI($M$9-$J$9,J29,M29) -> 0.078265466
B30: EBIT | D30: =D25-D29 -> 1538.6225 | E30: =E25-E29 -> 1822.747 | F30: =F25-F29 -> 1574.7386 | G30: =G25-G29 -> 2136.8496 | H30: =H25-H29 -> 2030.86 | I30: =I25-I29 -> 2435.1087 | J30: =J25-J29 -> 3001.9677 | K30: =K25-K29 -> 3615.8363 | ... R30: =R25-R29 -> 9014.4304 | T30: =_xlfn.RRI($M$9-$H$9,H30,M30) -> 0.19635893 | U30: =_xlfn.RRI($M$9-$J$9,J30,M30) -> 0.18356963
B32: EBIT Margin | D32: =D30/D13 -> 0.24721203 | E32: =E30/E13 -> 0.23423943 | F32: =F30/F13 -> 0.17998179 | G32: =G30/G13 -> 0.20676306 | H32: =H30/H13 -> 0.16636848 | I32: =I30/I13 -> 0.16905476 | J32: =J30/J13 -> 0.17889127 | K32: =K30/K13 -> 0.18736741 | ... R32: =R30/R13 -> 0.20850649
B34: Less: Interest | D34: ='Income Stmt'!E41 -> -20.1474 | E34: ='Income Stmt'!F41 -> -58.6104 | F34: ='Income Stmt'!G41 -> -44.469 | G34: ='Income Stmt'!H41 -> -33.5316 | H34: ='Income Stmt'!I41 -> -429.4 | I34: =Schedules!J246*-1 -> -561.47041 | J34: =Schedules!K246*-1 -> -503.42321 | K34: =Schedules!L246*-1 -> -534.83289 | L34: =Schedules!M246*-1 -> -576.99301 | M34: =Schedules!N246*-1 -> -614.8129 | N34: =Schedules!O246*-1 -> -567.30762 | O34: =Schedules!P246*-1 -> -513.11571 | P34: =Schedules!Q246*-1 -> -523.37837 | ... R34: =Schedules!S246*-1 -> -544.52208
B35: Add: Other Income | D35: ='Income Stmt'!E42 -> 161.4821 | E35: ='Income Stmt'!F42 -> 196.0296 | F35: ='Income Stmt'!G42 -> 128.5668 | G35: ='Income Stmt'!H42 -> 280.8579 | H35: ='Income Stmt'!I42 -> 536.79 | I35: =Schedules!J252 -> 432.1278 | J35: =Schedules!K252 -> 503.42889 | K35: =Schedules!L252 -> 578.94322 | L35: =Schedules!M252 -> 657.10055 | M35: =Schedules!N252 -> 735.95262 | N35: =Schedules!O252 -> 824.26694 | O35: =Schedules!P252 -> 923.17897 | P35: =Schedules!Q252 -> 1033.9604 | ... R35: =Schedules!S252 -> 1297
B36: Less: Share of net profit of associates and joint ventures | D36: ='Income Stmt'!E45*-1 -> -11.6771 | E36: ='Income Stmt'!F45*-1 -> -14.4477 | F36: ='Income Stmt'!G45*-1 -> -12.4242 | G36: ='Income Stmt'!H45*-1 -> -15.2135 | H36: ='Income Stmt'!I45*-1 -> -12.24 | I36: 0 | J36: 0 | K36: 0 | L36: 0 | M36: 0 | N36: 0 | O36: 0 | P36: 0 | Q36: 0 | R36: 0
B37: EBT | D37: =SUM(D30,D34:D36) -> 1668.2801 | E37: =SUM(E30,E34:E36) -> 1945.7185 | F37: =SUM(F30,F34:F36) -> 1646.4122 | G37: =SUM(G30,G34:G36) -> 2368.9624 | H37: =SUM(H30,H34:H36) -> 2126.01 | I37: =SUM(I30,I34:I36) -> 2305.7661 | J37: =SUM(J30,J34:J36) -> 3001.9734 | K37: =SUM(K30,K34:K36) -> 3659.9467 | ... R37: =SUM(R30,R34:R36) -> 9766.9083
B39: Less: Taxes | D39: ='Income Stmt'!E48 -> -398.5839 | E39: ='Income Stmt'!F48 -> -521.6435 | F39: ='Income Stmt'!G48 -> -361.5633 | G39: ='Income Stmt'!H48 -> -457.5865 | H39: ='Income Stmt'!I48 -> -509.74 | I39: =Schedules!J142 -> -576.44153 | J39: =Schedules!K142 -> -750.49335 | K39: =Schedules!L142 -> -914.98667 | L39: =Schedules!M142 -> -1089.6271 | M39: =Schedules!N142 -> -1274.5917 | N39: =Schedules!O142 -> -1467.4204 | O39: =Schedules!P142 -> -1683.635 | P39: =Schedules!Q142 -> -1908.056 | ... R39: =Schedules!S142 -> -2441.7271 | T39: =_xlfn.RRI($M$9-$H$9,H39,M39) -> 0.20116999 | U39: =_xlfn.RRI($M$9-$J$9,J39,M39) -> 0.19309423
B40: Net Income | D40: =SUM(D37,D39) -> 1269.6962 | E40: =SUM(E37,E39) -> 1424.075 | F40: =SUM(F37,F39) -> 1284.8489 | G40: =SUM(G37,G39) -> 1911.3759 | H40: =SUM(H37,H39) -> 1616.27 | I40: =SUM(I37,I39) -> 1729.3246 | J40: =SUM(J37,J39) -> 2251.4801 | K40: =SUM(K37,K39) -> 2744.96 | ... R40: =SUM(R37,R39) -> 7325.1812 | T40: =_xlfn.RRI($M$9-$H$9,H40,M40) -> 0.18794323 | U40: =_xlfn.RRI($M$9-$J$9,J40,M40) -> 0.19309423
B42: Sales Growth % | D42: =IFERROR(D13/C13-1,0) -> 0 | E42: =IFERROR(E13/D13-1,0) -> 0.2502703 | F42: =IFERROR(F13/E13-1,0) -> 0.12438104 | G42: =IFERROR(G13/F13-1,0) -> 0.18119364 | H42: =IFERROR(H13/G13-1,0) -> 0.18115784 | I42: =IFERROR(I13/H13-1,0) -> 0.18 | J42: =IFERROR(J13/I13-1,0) -> 0.165 | K42: =IFERROR(K13/J13-1,0) -> 0.15 | ... R42: =IFERROR(R13/Q13-1,0) -> 0.12 | T42: =_xlfn.RRI($M$9-$H$9,H42,M42) -> -0.079073809 | U42: =_xlfn.RRI($M$9-$J$9,J42,M42) -> -0.10071137
B43: Gross Profit Margins % | D43: =IFERROR(D15/D13,"NM") -> 0.71390772 | E43: =IFERROR(E15/E13,"NM") -> 0.68878606 | F43: =IFERROR(F15/F13,"NM") -> 0.66699076 | G43: =IFERROR(G15/G13,"NM") -> 0.68942759 | H43: =IFERROR(H15/H13,"NM") -> 0.68419431 | I43: =IFERROR(I15/I13,"NM") -> 0.66 | J43: =IFERROR(J15/J13,"NM") -> 0.666 | K43: =IFERROR(K15/K13,"NM") -> 0.672 | ... R43: =IFERROR(R15/R13,"NM") -> 0.684 | T43: =_xlfn.RRI($M$9-$H$9,H43,M43) -> -5.6807492e-05 | U43: =_xlfn.RRI($M$9-$J$9,J43,M43) -> 0.0089290439
B44: EBITDA Margins % | D44: =IFERROR(D25/D13,"NM") -> 0.26632711 | E44: =IFERROR(E25/E13,"NM") -> 0.2556515 | F44: =IFERROR(F25/F13,"NM") -> 0.21723215 | G44: =IFERROR(G25/G13,"NM") -> 0.24529836 | H44: =IFERROR(H25/H13,"NM") -> 0.21724093 | I44: =IFERROR(I25/I13,"NM") -> 0.215 | J44: =IFERROR(J25/J13,"NM") -> 0.221 | K44: =IFERROR(K25/K13,"NM") -> 0.227 | ... R44: =IFERROR(R25/R13,"NM") -> 0.239 | T44: =_xlfn.RRI($M$9-$H$9,H44,M44) -> 0.019274714 | U44: =_xlfn.RRI($M$9-$J$9,J44,M44) -> 0.026443879
B45: EBIT Margins % | D45: =IFERROR(D30/D13,"NM") -> 0.24721203 | E45: =IFERROR(E30/E13,"NM") -> 0.23423943 | F45: =IFERROR(F30/F13,"NM") -> 0.17998179 | G45: =IFERROR(G30/G13,"NM") -> 0.20676306 | H45: =IFERROR(H30/H13,"NM") -> 0.16636848 | I45: =IFERROR(I30/I13,"NM") -> 0.16905476 | J45: =IFERROR(J30/J13,"NM") -> 0.17889127 | K45: =IFERROR(K30/K13,"NM") -> 0.18736741 | ... R45: =IFERROR(R30/R13,"NM") -> 0.20850649 | T45: =_xlfn.RRI($M$9-$H$9,H45,M45) -> 0.040489167 | U45: =_xlfn.RRI($M$9-$J$9,J45,M45) -> 0.042853343
B46: Actual Tax Rate % | D46: =-D39/D37*-1 -> -0.23891905 | E46: =-E39/E37*-1 -> -0.26809813 | F46: =-F39/F37*-1 -> -0.21960679 | G46: =-G39/G37*-1 -> -0.19315904 | H46: =-H39/H37*-1 -> -0.23976369 | I46: =-I39/I37*-1 -> -0.25 | J46: =-J39/J37*-1 -> -0.25 | K46: =-K39/K37*-1 -> -0.25 | ... R46: =-R39/R37*-1 -> -0.25 | T46: =_xlfn.RRI($M$9-$H$9,H46,M46) -> 0.0083964762 | U46: =_xlfn.RRI($M$9-$J$9,J46,M46) -> 0
B47: Net Income Margin % | D47: =IFERROR(D40/D13,"NM") -> 0.20400337 | E47: =IFERROR(E40/E13,"NM") -> 0.18300648 | F47: =IFERROR(F40/F13,"NM") -> 0.14684939 | G47: =IFERROR(G40/G13,"NM") -> 0.18494607 | H47: =IFERROR(H40/H13,"NM") -> 0.13240518 | I47: =IFERROR(I40/I13,"NM") -> 0.12005647 | J47: =IFERROR(J40/J13,"NM") -> 0.1341687 | K47: =IFERROR(K40/K13,"NM") -> 0.14223986 | ... R47: =IFERROR(R40/R13,"NM") -> 0.16943365 | T47: =_xlfn.RRI($M$9-$H$9,H47,M47) -> 0.033169923 | U47: =_xlfn.RRI($M$9-$J$9,J47,M47) -> 0.051245552
A49: # | B49: Balance Sheet
B51: Assets
B53: Non Current Assets
B54: Property , Plants & Equipments | D54: ='Balance Sheet'!E7 -> 1620.2788 | E54: ='Balance Sheet'!F7 -> 1652.4046 | F54: ='Balance Sheet'!G7 -> 2409.4607 | G54: ='Balance Sheet'!H7 -> 2812.5396 | H54: ='Balance Sheet'!I7 -> 2740.6305 | I54: =Schedules!J62 -> 3216.7203 | J54: =Schedules!K62 -> 3712.1631 | K54: =Schedules!L62 -> 4363.6545 | L54: =Schedules!M62 -> 4987.4966 | M54: =Schedules!N62 -> 5559.1252 | N54: =Schedules!O62 -> 6179.3793 | O54: =Schedules!P62 -> 6854.0939 | P54: =Schedules!Q62 -> 7589.8042 | ... R54: =Schedules!S62 -> 9274.3685
B55: Right of Use Assets | D55: ='Balance Sheet'!E9 -> 0 | E55: ='Balance Sheet'!F9 -> 67.3571 | F55: ='Balance Sheet'!G9 -> 114.3647 | G55: ='Balance Sheet'!H9 -> 119.0613 | H55: ='Balance Sheet'!I9 -> 167.25 | I55: =Schedules!J69 -> 158.94935 | J55: =Schedules!K69 -> 150.6487 | K55: =Schedules!L69 -> 142.34804 | L55: =Schedules!M69 -> 134.04739 | M55: =Schedules!N69 -> 125.74674 | N55: =Schedules!O69 -> 117.44609 | O55: =Schedules!P69 -> 109.14543 | P55: =Schedules!Q69 -> 100.84478 | ... R55: =Schedules!S69 -> 84.243475
B56: Capital Work in Progress | D56: ='Balance Sheet'!E8 -> 371.6162 | E56: ='Balance Sheet'!F8 -> 669.8734 | F56: ='Balance Sheet'!G8 -> 493.192 | G56: ='Balance Sheet'!H8 -> 207.0939 | H56: ='Balance Sheet'!I8 -> 306.13 | I56: =Schedules!J75 -> 0 | J56: =Schedules!K75 -> 0 | K56: =Schedules!L75 -> 0 | L56: =Schedules!M75 -> 0 | M56: =Schedules!N75 -> 0 | N56: =Schedules!O75 -> 0 | O56: =Schedules!P75 -> 0 | P56: =Schedules!Q75 -> 0 | ... R56: =Schedules!S75 -> 0
...

Sheet CommonSizeStatement
B2: ='Input Sheet'!C5 -> Mankind Pharma Ltd
B3: Common Size Statement
H4: Current Case | J4: 1
D8: Actual | I8: Explicit Forecast Period | O8: 5 Years | P8: 3 Years
B9: In INR Crores unless stated otherwise | D9: ='ControlSheet '!E9 -> 2021 | E9: ='ControlSheet '!F9 -> 2022 | F9: ='ControlSheet '!G9 -> 2023 | G9: ='ControlSheet '!H9 -> 2024 | H9: ='ControlSheet '!I9 -> 2025 | I9: ='ControlSheet '!J9 -> 2026 | J9: ='ControlSheet '!K9 -> 2027 | K9: ='ControlSheet '!L9 -> 2028 | ... M9: ='ControlSheet '!N9 -> 2030
A11: # | B11: Income Statement
B13: Revenue | D13: ='3StatementModel'!D13/'3StatementModel'!D$13 -> 1 | E13: ='3StatementModel'!E13/'3StatementModel'!E$13 -> 1 | F13: ='3StatementModel'!F13/'3StatementModel'!F$13 -> 1 | G13: ='3StatementModel'!G13/'3StatementModel'!G$13 -> 1 | H13: ='3StatementModel'!H13/'3StatementModel'!H$13 -> 1 | I13: ='3StatementModel'!I13/'3StatementModel'!I$13 -> 1 | J13: ='3StatementModel'!J13/'3StatementModel'!J$13 -> 1 | K13: ='3StatementModel'!K13/'3StatementModel'!K$13 -> 1 | ... M13: ='3StatementModel'!M13/'3StatementModel'!M$13 -> 1 | O13: =_xlfn.RRI($M$9-$H$9,H13,M13) -> 0 | P13: =_xlfn.RRI($M$9-$J$9,J13,M13) -> 0
B14: Less: Cost of Goods Sold | D14: ='3StatementModel'!D14/'3StatementModel'!D$13*-1 -> 0.28609228 | E14: ='3StatementModel'!E14/'3StatementModel'!E$13*-1 -> 0.31121394 | F14: ='3StatementModel'!F14/'3StatementModel'!F$13*-1 -> 0.33300924 | G14: ='3StatementModel'!G14/'3StatementModel'!G$13*-1 -> 0.31057241 | H14: ='3StatementModel'!H14/'3StatementModel'!H$13*-1 -> 0.31580569 | I14: ='3StatementModel'!I14/'3StatementModel'!I$13*-1 -> 0.34 | J14: ='3StatementModel'!J14/'3StatementModel'!J$13*-1 -> 0.334 | K14: ='3StatementModel'!K14/'3StatementModel'!K$13*-1 -> 0.328 | ... M14: ='3StatementModel'!M14/'3StatementModel'!M$13*-1 -> 0.316 | O14: =_xlfn.RRI($M$9-$H$9,H14,M14) -> 0.00012302941 | P14: =_xlfn.RRI($M$9-$J$9,J14,M14) -> -0.018296803
B15: Gross Profit | D15: ='3StatementModel'!D15/'3StatementModel'!D$13 -> 0.71390772 | E15: ='3StatementModel'!E15/'3StatementModel'!E$13 -> 0.68878606 | F15: ='3StatementModel'!F15/'3StatementModel'!F$13 -> 0.66699076 | G15: ='3StatementModel'!G15/'3StatementModel'!G$13 -> 0.68942759 | H15: ='3StatementModel'!H15/'3StatementModel'!H$13 -> 0.68419431 | I15: ='3StatementModel'!I15/'3StatementModel'!I$13 -> 0.66 | J15: ='3StatementModel'!J15/'3StatementModel'!J$13 -> 0.666 | K15: ='3StatementModel'!K15/'3StatementModel'!K$13 -> 0.672 | ... M15: ='3StatementModel'!M15/'3StatementModel'!M$13 -> 0.684 | O15: =_xlfn.RRI($M$9-$H$9,H15,M15) -> -5.6807492e-05 | P15: =_xlfn.RRI($M$9-$J$9,J15,M15) -> 0.0089290439
B17: Gross Margin | D17: 0.71390772 | E17: 0.68878606 | F17: 0.66699076 | G17: 0.68942759 | H17: 0.68419431 | I17: 0.66 | J17: 0.666 | K17: 0.672 | L17: 0.678 | M17: 0.684
B19: Less: SG&A Expenses (Excluding Depreciation & Interest)
B20: Employee Benefit Expense | D20: ='3StatementModel'!D20/'3StatementModel'!D$13 -> 0.22747159 | E20: ='3StatementModel'!E20/'3StatementModel'!E$13 -> 0.20825914 | F20: ='3StatementModel'!F20/'3StatementModel'!F$13 -> 0.21926564 | G20: ='3StatementModel'!G20/'3StatementModel'!G$13 -> 0.22010156 | H20: ='3StatementModel'!H20/'3StatementModel'!H$13 -> 0.2205292 | I20: ='3StatementModel'!I20/'3StatementModel'!I$13 -> 0.22 | J20: ='3StatementModel'!J20/'3StatementModel'!J$13 -> 0.22 | K20: ='3StatementModel'!K20/'3StatementModel'!K$13 -> 0.22 | ... M20: ='3StatementModel'!M20/'3StatementModel'!M$13 -> 0.22 | O20: =_xlfn.RRI($M$9-$H$9,H20,M20) -> -0.00048040191 | P20: =_xlfn.RRI($M$9-$J$9,J20,M20) -> 0
B21: Advertising & Sales Promotion Expense | D21: ='3StatementModel'!D21/'3StatementModel'!D$13 -> 0.061977235 | E21: ='3StatementModel'!E21/'3StatementModel'!E$13 -> 0.058029532 | F21: ='3StatementModel'!F21/'3StatementModel'!F$13 -> 0.042707407 | G21: ='3StatementModel'!G21/'3StatementModel'!G$13 -> 0.058433031 | H21: ='3StatementModel'!H21/'3StatementModel'!H$13 -> 0.061849758 | I21: ='3StatementModel'!I21/'3StatementModel'!I$13 -> 0.058 | J21: ='3StatementModel'!J21/'3StatementModel'!J$13 -> 0.058 | K21: ='3StatementModel'!K21/'3StatementModel'!K$13 -> 0.058 | ... M21: ='3StatementModel'!M21/'3StatementModel'!M$13 -> 0.058 | O21: =_xlfn.RRI($M$9-$H$9,H21,M21) -> -0.012770789 | P21: =_xlfn.RRI($M$9-$J$9,J21,M21) -> 0
B22: Travelling and conveyance Expense | D22: ='3StatementModel'!D22/'3StatementModel'!D$13 -> 0.043445441 | E22: ='3StatementModel'!E22/'3StatementModel'!E$13 -> 0.046020364 | F22: ='3StatementModel'!F22/'3StatementModel'!F$13 -> 0.056694748 | G22: ='3StatementModel'!G22/'3StatementModel'!G$13 -> 0.036614267 | H22: ='3StatementModel'!H22/'3StatementModel'!H$13 -> 0.037765217 | I22: ='3StatementModel'!I22/'3StatementModel'!I$13 -> 0.046 | J22: ='3StatementModel'!J22/'3StatementModel'!J$13 -> 0.046 | K22: ='3StatementModel'!K22/'3StatementModel'!K$13 -> 0.046 | ... M22: ='3StatementModel'!M22/'3StatementModel'!M$13 -> 0.046 | O22: =_xlfn.RRI($M$9-$H$9,H22,M22) -> 0.040239091 | P22: =_xlfn.RRI($M$9-$J$9,J22,M22) -> 0
B23: Other Operating Expense | D23: ='3StatementModel'!D23/'3StatementModel'!D$13 -> 0.059441846 | E23: ='3StatementModel'!E23/'3StatementModel'!E$13 -> 0.065664253 | F23: ='3StatementModel'!F23/'3StatementModel'!F$13 -> 0.070768529 | G23: ='3StatementModel'!G23/'3StatementModel'!G$13 -> 0.077786834 | H23: ='3StatementModel'!H23/'3StatementModel'!H$13 -> 0.087900385 | I23: ='3StatementModel'!I23/'3StatementModel'!I$13 -> 0.066 | J23: ='3StatementModel'!J23/'3StatementModel'!J$13 -> 0.066 | K23: ='3StatementModel'!K23/'3StatementModel'!K$13 -> 0.066 | ... M23: ='3StatementModel'!M23/'3StatementModel'!M$13 -> 0.066 | O23: =_xlfn.RRI($M$9-$H$9,H23,M23) -> -0.055698604 | P23: =_xlfn.RRI($M$9-$J$9,J23,M23) -> 0
B24: Other Misc SG&A Expenses | D24: ='3StatementModel'!D24/'3StatementModel'!D$13 -> 0.055244509 | E24: ='3StatementModel'!E24/'3StatementModel'!E$13 -> 0.055161275 | F24: ='3StatementModel'!F24/'3StatementModel'!F$13 -> 0.060322297 | G24: ='3StatementModel'!G24/'3StatementModel'!G$13 -> 0.051193531 | H24: ='3StatementModel'!H24/'3StatementModel'!H$13 -> 0.058908823 | I24: ='3StatementModel'!I24/'3StatementModel'!I$13 -> 0.055 | J24: ='3StatementModel'!J24/'3StatementModel'!J$13 -> 0.055 | K24: ='3StatementModel'!K24/'3StatementModel'!K$13 -> 0.055 | ... M24: ='3StatementModel'!M24/'3StatementModel'!M$13 -> 0.055 | O24: =_xlfn.RRI($M$9-$H$9,H24,M24) -> -0.01363769 | P24: =_xlfn.RRI($M$9-$J$9,J24,M24) -> 0
B25: EBITDA | D25: ='3StatementModel'!D25/'3StatementModel'!D$13 -> 0.26632711 | E25: ='3StatementModel'!E25/'3StatementModel'!E$13 -> 0.2556515 | F25: ='3StatementModel'!F25/'3StatementModel'!F$13 -> 0.21723215 | G25: ='3StatementModel'!G25/'3StatementModel'!G$13 -> 0.24529836 | H25: ='3StatementModel'!H25/'3StatementModel'!H$13 -> 0.21724093 | I25: ='3StatementModel'!I25/'3StatementModel'!I$13 -> 0.215 | J25: ='3StatementModel'!J25/'3StatementModel'!J$13 -> 0.221 | K25: ='3StatementModel'!K25/'3StatementModel'!K$13 -> 0.227 | ... M25: ='3StatementModel'!M25/'3StatementModel'!M$13 -> 0.239 | O25: =_xlfn.RRI($M$9-$H$9,H25,M25) -> 0.019274714 | P25: =_xlfn.RRI($M$9-$J$9,J25,M25) -> 0.026443879
B27: EBITDA Margin | D27: 0.26632711 | E27: 0.2556515 | F27: 0.21723215 | G27: 0.24529836 | H27: 0.21724093 | I27: 0.215 | J27: 0.221 | K27: 0.227 | L27: 0.233 | M27: 0.239
B29: Less: Depreciation | D29: ='3StatementModel'!D29/'3StatementModel'!D$13 -> 0.019115078 | E29: ='3StatementModel'!E29/'3StatementModel'!E$13 -> 0.02141207 | F29: ='3StatementModel'!F29/'3StatementModel'!F$13 -> 0.037250357 | G29: ='3StatementModel'!G29/'3StatementModel'!G$13 -> 0.038535306 | H29: ='3StatementModel'!H29/'3StatementModel'!H$13 -> 0.05087245 | I29: ='3StatementModel'!I29/'3StatementModel'!I$13 -> 0.04594524 | J29: ='3StatementModel'!J29/'3StatementModel'!J$13 -> 0.042108732 | K29: ='3StatementModel'!K29/'3StatementModel'!K$13 -> 0.039632593 | ... M29: ='3StatementModel'!M29/'3StatementModel'!M$13 -> 0.036110834 | O29: =_xlfn.RRI($M$9-$H$9,H29,M29) -> -0.066249228 | P29: =_xlfn.RRI($M$9-$J$9,J29,M29) -> -0.049931058
B30: EBIT | D30: ='3StatementModel'!D30/'3StatementModel'!D$13 -> 0.24721203 | E30: ='3StatementModel'!E30/'3StatementModel'!E$13 -> 0.23423943 | F30: ='3StatementModel'!F30/'3StatementModel'!F$13 -> 0.17998179 | G30: ='3StatementModel'!G30/'3StatementModel'!G$13 -> 0.20676306 | H30: ='3StatementModel'!H30/'3StatementModel'!H$13 -> 0.16636848 | I30: ='3StatementModel'!I30/'3StatementModel'!I$13 -> 0.16905476 | J30: ='3StatementModel'!J30/'3StatementModel'!J$13 -> 0.17889127 | K30: ='3StatementModel'!K30/'3StatementModel'!K$13 -> 0.18736741 | ... M30: ='3StatementModel'!M30/'3StatementModel'!M$13 -> 0.20288917 | O30: =_xlfn.RRI($M$9-$H$9,H30,M30) -> 0.040489167 | P30: =_xlfn.RRI($M$9-$J$9,J30,M30) -> 0.042853343
B32: EBIT Margin | D32: 0.24721203 | E32: 0.23423943 | F32: 0.17998179 | G32: 0.20676306 | H32: 0.16636848 | I32: 0.16905476 | J32: 0.17889127 | K32: 0.18736741 | L32: 0.19533087 | M32: 0.20288917
B34: Less: Interest | D34: ='3StatementModel'!D34/'3StatementModel'!D$13 -> -0.0032371031 | E34: ='3StatementModel'!E34/'3StatementModel'!E$13 -> -0.0075319649 | F34: ='3StatementModel'!F34/'3StatementModel'!F$13 -> -0.0050825008 | G34: ='3StatementModel'!G34/'3StatementModel'!G$13 -> -0.003244541 | H34: ='3StatementModel'!H34/'3StatementModel'!H$13 -> -0.035176538 | I34: ='3StatementModel'!I34/'3StatementModel'!I$13 -> -0.038979469 | J34: ='3StatementModel'!J34/'3StatementModel'!J$13 -> -0.029999662 | K34: ='3StatementModel'!K34/'3StatementModel'!K$13 -> -0.027714266 | ... M34: ='3StatementModel'!M34/'3StatementModel'!M$13 -> -0.025061922
B35: Add: Other Income | D35: ='3StatementModel'!D35/'3StatementModel'!D$13 -> 0.025945492 | E35: ='3StatementModel'!E35/'3StatementModel'!E$13 -> 0.025191571 | F35: ='3StatementModel'!F35/'3StatementModel'!F$13 -> 0.014694301 | G35: ='3StatementModel'!G35/'3StatementModel'!G$13 -> 0.027176006 | H35: ='3StatementModel'!H35/'3StatementModel'!H$13 -> 0.043973949 | I35: ='3StatementModel'!I35/'3StatementModel'!I$13 -> 0.03 | J35: ='3StatementModel'!J35/'3StatementModel'!J$13 -> 0.03 | K35: ='3StatementModel'!K35/'3StatementModel'!K$13 -> 0.03 | ... M35: ='3StatementModel'!M35/'3StatementModel'!M$13 -> 0.03
B36: Less: Share of net profit of associates and joint ventures | D36: ='3StatementModel'!D36/'3StatementModel'!D$13 -> -0.0018761714 | E36: ='3StatementModel'!E36/'3StatementModel'!E$13 -> -0.0018566597 | F36: ='3StatementModel'!F36/'3StatementModel'!F$13 -> -0.0014200006 | G36: ='3StatementModel'!G36/'3StatementModel'!G$13 -> -0.0014720689 | H36: ='3StatementModel'!H36/'3StatementModel'!H$13 -> -0.0010027034 | I36: ='3StatementModel'!I36/'3StatementModel'!I$13 -> 0 | J36: ='3StatementModel'!J36/'3StatementModel'!J$13 -> 0 | K36: ='3StatementModel'!K36/'3StatementModel'!K$13 -> 0 | ... M36: ='3StatementModel'!M36/'3StatementModel'!M$13 -> 0
B37: EBT | D37: ='3StatementModel'!D37/'3StatementModel'!D$13 -> 0.26804425 | E37: ='3StatementModel'!E37/'3StatementModel'!E$13 -> 0.25004237 | F37: ='3StatementModel'!F37/'3StatementModel'!F$13 -> 0.18817359 | G37: ='3StatementModel'!G37/'3StatementModel'!G$13 -> 0.22922245 | H37: ='3StatementModel'!H37/'3StatementModel'!H$13 -> 0.17416319 | I37: ='3StatementModel'!I37/'3StatementModel'!I$13 -> 0.16007529 | J37: ='3StatementModel'!J37/'3StatementModel'!J$13 -> 0.17889161 | K37: ='3StatementModel'!K37/'3StatementModel'!K$13 -> 0.18965314 | ... M37: ='3StatementModel'!M37/'3StatementModel'!M$13 -> 0.20782724
B39: Less: Taxes | D39: ='3StatementModel'!D39/'3StatementModel'!D$13 -> -0.064040877 | E39: ='3StatementModel'!E39/'3StatementModel'!E$13 -> -0.067035894 | F39: ='3StatementModel'!F39/'3StatementModel'!F$13 -> -0.041324198 | G39: ='3StatementModel'!G39/'3StatementModel'!G$13 -> -0.044276389 | H39: ='3StatementModel'!H39/'3StatementModel'!H$13 -> -0.041758008 | I39: ='3StatementModel'!I39/'3StatementModel'!I$13 -> -0.040018823 | J39: ='3StatementModel'!J39/'3StatementModel'!J$13 -> -0.044722902 | K39: ='3StatementModel'!K39/'3StatementModel'!K$13 -> -0.047413285 | ... M39: ='3StatementModel'!M39/'3StatementModel'!M$13 -> -0.051956811 | O39: =_xlfn.RRI($M$9-$H$9,H39,M39) -> 0.044673416 | P39: =_xlfn.RRI($M$9-$J$9,J39,M39) -> 0.051245552
B40: Net Income | D40: ='3StatementModel'!D40/'3StatementModel'!D$13 -> 0.20400337 | E40: ='3StatementModel'!E40/'3StatementModel'!E$13 -> 0.18300648 | F40: ='3StatementModel'!F40/'3StatementModel'!F$13 -> 0.14684939 | G40: ='3StatementModel'!G40/'3StatementModel'!G$13 -> 0.18494607 | H40: ='3StatementModel'!H40/'3StatementModel'!H$13 -> 0.13240518 | I40: ='3StatementModel'!I40/'3StatementModel'!I$13 -> 0.12005647 | J40: ='3StatementModel'!J40/'3StatementModel'!J$13 -> 0.1341687 | K40: ='3StatementModel'!K40/'3StatementModel'!K$13 -> 0.14223986 | ... M40: ='3StatementModel'!M40/'3StatementModel'!M$13 -> 0.15587043 | O40: =_xlfn.RRI($M$9-$H$9,H40,M40) -> 0.033169923 | P40: =_xlfn.RRI($M$9-$J$9,J40,M40) -> 0.051245552
B42: Sales Growth % | D42: 0 | E42: 0.2502703 | F42: 0.12438104 | G42: 0.18119364 | H42: 0.18115784 | I42: 0.18 | J42: 0.165 | K42: 0.15 | L42: 0.135 | M42: 0.12
B43: Gross Profit Margins % | D43: 0.71390772 | E43: 0.68878606 | F43: 0.66699076 | G43: 0.68942759 | H43: 0.68419431 | I43: 0.66 | J43: 0.666 | K43: 0.672 | L43: 0.678 | M43: 0.684
B44: EBITDA Margins % | D44: 0.26632711 | E44: 0.2556515 | F44: 0.21723215 | G44: 0.24529836 | H44: 0.21724093 | I44: 0.215 | J44: 0.221 | K44: 0.227 | L44: 0.233 | M44: 0.239
B45: EBIT Margins % | D45: 0.24721203 | E45: 0.23423943 | F45: 0.17998179 | G45: 0.20676306 | H45: 0.16636848 | I45: 0.16905476 | J45: 0.17889127 | K45: 0.18736741 | L45: 0.19533087 | M45: 0.20288917
B46: Actual Tax Rate % | D46: -0.23891905 | E46: -0.26809813 | F46: -0.21960679 | G46: -0.19315904 | H46: -0.23976369 | I46: -0.25 | J46: -0.25 | K46: -0.25 | L46: -0.25 | M46: -0.25
B47: Net Income Margin % | D47: 0.20400337 | E47: 0.18300648 | F47: 0.14684939 | G47: 0.18494607 | H47: 0.13240518 | I47: 0.12005647 | J47: 0.1341687 | K47: 0.14223986 | L47: 0.14924114 | M47: 0.15587043
A49: # | B49: Balance Sheet
B51: Assets
B53: Non Current Assets
B54: Property , Plants & Equipments | D54: ='3StatementModel'!D54/'3StatementModel'!D$76 -> 0.2542478 | E54: ='3StatementModel'!E54/'3StatementModel'!E$76 -> 0.18063428 | F54: ='3StatementModel'!F54/'3StatementModel'!F$76 -> 0.24800234 | G54: ='3StatementModel'!G54/'3StatementModel'!G$76 -> 0.23509804 | H54: ='3StatementModel'!H54/'3StatementModel'!H$76 -> 0.098727339 | I54: ='3StatementModel'!I54/'3StatementModel'!I$76 -> 0.1148613 | J54: ='3StatementModel'!J54/'3StatementModel'!J$76 -> 0.12014148 | K54: ='3StatementModel'!K54/'3StatementModel'!K$76 -> 0.12717557 | ... M54: ='3StatementModel'!M54/'3StatementModel'!M$76 -> 0.12963452
B55: Right of Use Assets | D55: ='3StatementModel'!D55/'3StatementModel'!D$76 -> 0 | E55: ='3StatementModel'!E55/'3StatementModel'!E$76 -> 0.0073632095 | F55: ='3StatementModel'!F55/'3StatementModel'!F$76 -> 0.011771395 | G55: ='3StatementModel'!G55/'3StatementModel'!G$76 -> 0.0099522432 | H55: ='3StatementModel'!H55/'3StatementModel'!H$76 -> 0.0060249448 | I55: ='3StatementModel'!I55/'3StatementModel'!I$76 -> 0.0056756968 | J55: ='3StatementModel'!J55/'3StatementModel'!J$76 -> 0.0048756361 | K55: ='3StatementModel'!K55/'3StatementModel'!K$76 -> 0.0041486314 | ... M55: ='3StatementModel'!M55/'3StatementModel'!M$76 -> 0.0029323171
B56: Capital Work in Progress | D56: ='3StatementModel'!D56/'3StatementModel'!D$76 -> 0.058312557 | E56: ='3StatementModel'!E56/'3StatementModel'!E$76 -> 0.073227888 | F56: ='3StatementModel'!F56/'3StatementModel'!F$76 -> 0.050763547 | G56: ='3StatementModel'!G56/'3StatementModel'!G$76 -> 0.017310821 | H56: ='3StatementModel'!H56/'3StatementModel'!H$76 -> 0.0110279 | I56: ='3StatementModel'!I56/'3StatementModel'!I$76 -> 0 | J56: ='3StatementModel'!J56/'3StatementModel'!J$76 -> 0 | K56: ='3StatementModel'!K56/'3StatementModel'!K$76 -> 0 | ... M56: ='3StatementModel'!M56/'3StatementModel'!M$76 -> 0
B57: Goodwill | D57: ='3StatementModel'!D57/'3StatementModel'!D$76 -> 0.0032077099 | E57: ='3StatementModel'!E57/'3StatementModel'!E$76 -> 0.0022346598 | F57: ='3StatementModel'!F57/'3StatementModel'!F$76 -> 0.0020608873 | G57: ='3StatementModel'!G57/'3StatementModel'!G$76 -> 0.0016736655 | H57: ='3StatementModel'!H57/'3StatementModel'!H$76 -> 0.23386512 | I57: ='3StatementModel'!I57/'3StatementModel'!I$76 -> 0.23181362 | J57: ='3StatementModel'!J57/'3StatementModel'!J$76 -> 0.21010889 | K57: ='3StatementModel'!K57/'3StatementModel'!K$76 -> 0.18920467 | ... M57: ='3StatementModel'!M57/'3StatementModel'!M$76 -> 0.15138844
...

Sheet Ratios
B2: ='Input Sheet'!C5 -> Mankind Pharma Ltd
B3: Common Size Statement
F4: Current Case | H4: 1
D8: Actual | I8: Explicit Forecasted Period
B9: In INR Crores unless stated otherwise | D9: 2021 | E9: =D9+1 -> 2022 | F9: =E9+1 -> 2023 | G9: =F9+1 -> 2024 | H9: =G9+1 -> 2025 | I9: =H9+1 -> 2026 | J9: =I9+1 -> 2027 | K9: =J9+1 -> 2028 | L9: =K9+1 -> 2029 | M9: =L9+1 -> 2030
A11: # | B11: Liquidity Ratios
B13: Current Assets | D13: ='3StatementModel'!D74 -> 3906.6348 | E13: ='3StatementModel'!E74 -> 4406.8183 | F13: ='3StatementModel'!F74 -> 4327.872 | G13: ='3StatementModel'!G74 -> 6568.2272 | H13: ='3StatementModel'!H74 -> 6988.27 | I13: ='3StatementModel'!I74 -> 7548.9588 | J13: ='3StatementModel'!J74 -> 10431.506 | K13: ='3StatementModel'!K74 -> 13678.78 | ... M13: ='3StatementModel'!M74 -> 22024.287
B14: Current Liabilities | D14: ='3StatementModel'!D83 -> 4722.0038 | E14: ='3StatementModel'!E83 -> 6155.2321 | F14: ='3StatementModel'!F83 -> 7435.6228 | G14: ='3StatementModel'!G83 -> 9363.0881 | H14: ='3StatementModel'!H83 -> 14332.39 | I14: ='3StatementModel'!I83 -> 16061.715 | J14: ='3StatementModel'!J83 -> 18313.195 | K14: ='3StatementModel'!K83 -> 21058.155 | ... M14: ='3StatementModel'!M83 -> 28150.811
B15: Current Ratio | D15: =D13/D14 -> 0.82732564 | E15: =E13/E14 -> 0.71594673 | F15: =F13/F14 -> 0.58204566 | G15: =G13/G14 -> 0.70150223 | H15: =H13/H14 -> 0.48758581 | I15: =I13/I14 -> 0.46999707 | J15: =J13/J14 -> 0.56961693 | K15: =K13/K14 -> 0.64957165 | ... M15: =M13/M14 -> 0.78236776
B17: Current Assets | D17: =D13 -> 3906.6348 | E17: =E13 -> 4406.8183 | F17: =F13 -> 4327.872 | G17: =G13 -> 6568.2272 | H17: =H13 -> 6988.27 | I17: =I13 -> 7548.9588 | J17: =J13 -> 10431.506 | K17: =K13 -> 13678.78 | ... M17: =M13 -> 22024.287
B18: Inventory | D18: ='3StatementModel'!D70 -> 1183.5377 | E18: ='3StatementModel'!E70 -> 1760.2381 | F18: ='3StatementModel'!F70 -> 1498.4582 | G18: ='3StatementModel'!G70 -> 1553.4612 | H18: ='3StatementModel'!H70 -> 2093.71 | I18: ='3StatementModel'!I70 -> 2311.8153 | J18: ='3StatementModel'!J70 -> 2693.2648 | K18: ='3StatementModel'!K70 -> 2907.934 | ... M18: ='3StatementModel'!M70 -> 3696.5657
B19: Other Current Assets | D19: ='3StatementModel'!D73 -> 385.5699 | E19: ='3StatementModel'!E73 -> 978.0109 | F19: ='3StatementModel'!F73 -> 724.3197 | G19: ='3StatementModel'!G73 -> 710.4012 | H19: ='3StatementModel'!H73 -> 1110.88 | I19: ='3StatementModel'!I73 -> 993.89394 | J19: ='3StatementModel'!J73 -> 1157.8864 | K19: ='3StatementModel'!K73 -> 1331.5694 | ... M19: ='3StatementModel'!M73 -> 1692.691
B20: Current Liabilities | D20: =D14 -> 4722.0038 | E20: =E14 -> 6155.2321 | F20: =F14 -> 7435.6228 | G20: =G14 -> 9363.0881 | H20: =H14 -> 14332.39 | I20: =I14 -> 16061.715 | J20: =J14 -> 18313.195 | K20: =K14 -> 21058.155 | ... M20: =M14 -> 28150.811
B21: Quick Ratio (Acid Test Ratio) | D21: =(D17-D18-D19)/D20 -> 0.49502866 | E21: =(E17-E18-E19)/E20 -> 0.27108146 | F21: =(F17-F18-F19)/F20 -> 0.28310932 | G21: =(G17-G18-G19)/G20 -> 0.45971636 | H21: =(H17-H18-H19)/H20 -> 0.26399505 | I21: =(I17-I18-I19)/I20 -> 0.26418409 | J21: =(J17-J18-J19)/J20 -> 0.35932313 | K21: =(K17-K18-K19)/K20 -> 0.44824806 | ... M21: =(M17-M18-M19)/M20 -> 0.59092544
B23: Inventory Days | D23: ='3StatementModel'!D113 -> 0 | E23: ='3StatementModel'!E113 -> 69.040067 | F23: ='3StatementModel'!F113 -> 67.971499 | G23: ='3StatementModel'!G113 -> 53.893318 | H23: ='3StatementModel'!H113 -> 54.526808 | I23: ='3StatementModel'!I113 -> 58.580766 | J23: ='3StatementModel'!J113 -> 58.580766 | K23: ='3StatementModel'!K113 -> 55 | ... M23: ='3StatementModel'!M113 -> 55
B24: Debtor Days | D24: ='3StatementModel'!D112 -> 0 | E24: ='3StatementModel'!E112 -> 16.857409 | F24: ='3StatementModel'!F112 -> 20.119841 | G24: ='3StatementModel'!G112 -> 25.158577 | H24: ='3StatementModel'!H112 -> 35.681033 | I24: ='3StatementModel'!I112 -> 23.823919 | J24: ='3StatementModel'!J112 -> 23.823919 | K24: ='3StatementModel'!K112 -> 25 | ... M24: ='3StatementModel'!M112 -> 25
B25: Creditor Days | D25: ='3StatementModel'!D114 -> 0 | E25: ='3StatementModel'!E114 -> 131.39713 | F25: ='3StatementModel'!F114 -> 130.54688 | G25: ='3StatementModel'!G114 -> 120.01576 | H25: ='3StatementModel'!H114 -> 105.87538 | I25: ='3StatementModel'!I114 -> 120 | J25: ='3StatementModel'!J114 -> 120 | K25: ='3StatementModel'!K114 -> 120 | ... M25: ='3StatementModel'!M114 -> 120
B26: Cash Conversion Days | D26: =D23+D24-D25 -> 0 | E26: =E23+E24-E25 -> -45.499649 | F26: =F23+F24-F25 -> -42.455544 | G26: =G23+G24-G25 -> -40.963862 | H26: =H23+H24-H25 -> -15.667538 | I26: =I23+I24-I25 -> -37.595315 | J26: =J23+J24-J25 -> -37.595315 | K26: =K23+K24-K25 -> -40 | ... M26: =M23+M24-M25 -> -40
A28: # | B28: Leverage Ratios / Solvency Ratios
